2019-03-01 11:11:47,546 - __main__ - ERROR - Exception on /convert [POST]
Traceback (most recent call last):
  File "/home/django/.local/share/virtualenvs/flask-backend-4nHDySRL/lib/python3.6/site-packages/flask/app.py", line 1817, in wsgi_app
    response = self.full_dispatch_request()
  File "/home/django/.local/share/virtualenvs/flask-backend-4nHDySRL/lib/python3.6/site-packages/flask/app.py", line 1477, in full_dispatch_request
    rv = self.handle_user_exception(e)
  File "/home/django/.local/share/virtualenvs/flask-backend-4nHDySRL/lib/python3.6/site-packages/flask_cors/extension.py", line 161, in wrapped_function
    return cors_after_request(app.make_response(f(*args, **kwargs)))
  File "/home/django/.local/share/virtualenvs/flask-backend-4nHDySRL/lib/python3.6/site-packages/flask/app.py", line 1381, in handle_user_exception
    reraise(exc_type, exc_value, tb)
  File "/home/django/.local/share/virtualenvs/flask-backend-4nHDySRL/lib/python3.6/site-packages/flask/_compat.py", line 33, in reraise
    raise value
  File "/home/django/.local/share/virtualenvs/flask-backend-4nHDySRL/lib/python3.6/site-packages/flask/app.py", line 1475, in full_dispatch_request
    rv = self.dispatch_request()
  File "/home/django/.local/share/virtualenvs/flask-backend-4nHDySRL/lib/python3.6/site-packages/flask/app.py", line 1461, in dispatch_request
    return self.view_functions[rule.endpoint](**req.view_args)
  File "parser.py", line 121, in convert
    values = str(add_metadata) + json_request['request_info']['values'] + "}"
UnboundLocalError: local variable 'add_metadata' referenced before assignment
2019-03-01 11:12:01,897 - __main__ - ERROR - Exception on /convert [POST]
Traceback (most recent call last):
  File "/home/django/.local/share/virtualenvs/flask-backend-4nHDySRL/lib/python3.6/site-packages/flask/app.py", line 1817, in wsgi_app
    response = self.full_dispatch_request()
  File "/home/django/.local/share/virtualenvs/flask-backend-4nHDySRL/lib/python3.6/site-packages/flask/app.py", line 1477, in full_dispatch_request
    rv = self.handle_user_exception(e)
  File "/home/django/.local/share/virtualenvs/flask-backend-4nHDySRL/lib/python3.6/site-packages/flask_cors/extension.py", line 161, in wrapped_function
    return cors_after_request(app.make_response(f(*args, **kwargs)))
  File "/home/django/.local/share/virtualenvs/flask-backend-4nHDySRL/lib/python3.6/site-packages/flask/app.py", line 1381, in handle_user_exception
    reraise(exc_type, exc_value, tb)
  File "/home/django/.local/share/virtualenvs/flask-backend-4nHDySRL/lib/python3.6/site-packages/flask/_compat.py", line 33, in reraise
    raise value
  File "/home/django/.local/share/virtualenvs/flask-backend-4nHDySRL/lib/python3.6/site-packages/flask/app.py", line 1475, in full_dispatch_request
    rv = self.dispatch_request()
  File "/home/django/.local/share/virtualenvs/flask-backend-4nHDySRL/lib/python3.6/site-packages/flask/app.py", line 1461, in dispatch_request
    return self.view_functions[rule.endpoint](**req.view_args)
  File "parser.py", line 121, in convert
    values = str(add_metadata) + json_request['request_info']['values'] + "}"
UnboundLocalError: local variable 'add_metadata' referenced before assignment
