2019-02-17 19:44:51,556 - __main__ - ERROR - Exception on /convert [POST]
Traceback (most recent call last):
  File "/home/django/.local/share/virtualenvs/flask-backend-4nHDySRL/lib/python3.6/site-packages/flask/app.py", line 1817, in wsgi_app
    response = self.full_dispatch_request()
  File "/home/django/.local/share/virtualenvs/flask-backend-4nHDySRL/lib/python3.6/site-packages/flask/app.py", line 1477, in full_dispatch_request
    rv = self.handle_user_exception(e)
  File "/home/django/.local/share/virtualenvs/flask-backend-4nHDySRL/lib/python3.6/site-packages/flask_cors/extension.py", line 161, in wrapped_function
    return cors_after_request(app.make_response(f(*args, **kwargs)))
  File "/home/django/.local/share/virtualenvs/flask-backend-4nHDySRL/lib/python3.6/site-packages/flask/app.py", line 1381, in handle_user_exception
    reraise(exc_type, exc_value, tb)
  File "/home/django/.local/share/virtualenvs/flask-backend-4nHDySRL/lib/python3.6/site-packages/flask/_compat.py", line 33, in reraise
    raise value
  File "/home/django/.local/share/virtualenvs/flask-backend-4nHDySRL/lib/python3.6/site-packages/flask/app.py", line 1475, in full_dispatch_request
    rv = self.dispatch_request()
  File "/home/django/.local/share/virtualenvs/flask-backend-4nHDySRL/lib/python3.6/site-packages/flask/app.py", line 1461, in dispatch_request
    return self.view_functions[rule.endpoint](**req.view_args)
  File "parser.py", line 95, in convert
    rendered_jinja2_tpl = jinja2_tpl.render(values)
  File "/home/django/.local/share/virtualenvs/flask-backend-4nHDySRL/lib/python3.6/site-packages/jinja2/environment.py", line 969, in render
    return self.environment.handle_exception(exc_info, True)
  File "/home/django/.local/share/virtualenvs/flask-backend-4nHDySRL/lib/python3.6/site-packages/jinja2/environment.py", line 742, in handle_exception
    reraise(exc_type, exc_value, tb)
  File "/home/django/.local/share/virtualenvs/flask-backend-4nHDySRL/lib/python3.6/site-packages/jinja2/_compat.py", line 36, in reraise
    raise value.with_traceback(tb)
  File "<template>", line 1, in <module>
AttributeError: 'str' object has no attribute '__call__'
2019-02-17 20:10:37,191 - __main__ - ERROR - Exception on /convert [POST]
Traceback (most recent call last):
  File "/home/django/.local/share/virtualenvs/flask-backend-4nHDySRL/lib/python3.6/site-packages/flask/app.py", line 1817, in wsgi_app
    response = self.full_dispatch_request()
  File "/home/django/.local/share/virtualenvs/flask-backend-4nHDySRL/lib/python3.6/site-packages/flask/app.py", line 1477, in full_dispatch_request
    rv = self.handle_user_exception(e)
  File "/home/django/.local/share/virtualenvs/flask-backend-4nHDySRL/lib/python3.6/site-packages/flask_cors/extension.py", line 161, in wrapped_function
    return cors_after_request(app.make_response(f(*args, **kwargs)))
  File "/home/django/.local/share/virtualenvs/flask-backend-4nHDySRL/lib/python3.6/site-packages/flask/app.py", line 1381, in handle_user_exception
    reraise(exc_type, exc_value, tb)
  File "/home/django/.local/share/virtualenvs/flask-backend-4nHDySRL/lib/python3.6/site-packages/flask/_compat.py", line 33, in reraise
    raise value
  File "/home/django/.local/share/virtualenvs/flask-backend-4nHDySRL/lib/python3.6/site-packages/flask/app.py", line 1475, in full_dispatch_request
    rv = self.dispatch_request()
  File "/home/django/.local/share/virtualenvs/flask-backend-4nHDySRL/lib/python3.6/site-packages/flask/app.py", line 1461, in dispatch_request
    return self.view_functions[rule.endpoint](**req.view_args)
  File "parser.py", line 95, in convert
    rendered_jinja2_tpl = jinja2_tpl.render(values)
  File "/home/django/.local/share/virtualenvs/flask-backend-4nHDySRL/lib/python3.6/site-packages/jinja2/environment.py", line 969, in render
    return self.environment.handle_exception(exc_info, True)
  File "/home/django/.local/share/virtualenvs/flask-backend-4nHDySRL/lib/python3.6/site-packages/jinja2/environment.py", line 742, in handle_exception
    reraise(exc_type, exc_value, tb)
  File "/home/django/.local/share/virtualenvs/flask-backend-4nHDySRL/lib/python3.6/site-packages/jinja2/_compat.py", line 36, in reraise
    raise value.with_traceback(tb)
  File "<template>", line 1, in <module>
AttributeError: 'str' object has no attribute '__call__'
2019-02-17 22:57:01,736 - __main__ - ERROR - Exception on /convert [POST]
Traceback (most recent call last):
  File "/home/django/.local/share/virtualenvs/flask-backend-4nHDySRL/lib/python3.6/site-packages/flask/app.py", line 1817, in wsgi_app
    response = self.full_dispatch_request()
  File "/home/django/.local/share/virtualenvs/flask-backend-4nHDySRL/lib/python3.6/site-packages/flask/app.py", line 1477, in full_dispatch_request
    rv = self.handle_user_exception(e)
  File "/home/django/.local/share/virtualenvs/flask-backend-4nHDySRL/lib/python3.6/site-packages/flask_cors/extension.py", line 161, in wrapped_function
    return cors_after_request(app.make_response(f(*args, **kwargs)))
  File "/home/django/.local/share/virtualenvs/flask-backend-4nHDySRL/lib/python3.6/site-packages/flask/app.py", line 1381, in handle_user_exception
    reraise(exc_type, exc_value, tb)
  File "/home/django/.local/share/virtualenvs/flask-backend-4nHDySRL/lib/python3.6/site-packages/flask/_compat.py", line 33, in reraise
    raise value
  File "/home/django/.local/share/virtualenvs/flask-backend-4nHDySRL/lib/python3.6/site-packages/flask/app.py", line 1475, in full_dispatch_request
    rv = self.dispatch_request()
  File "/home/django/.local/share/virtualenvs/flask-backend-4nHDySRL/lib/python3.6/site-packages/flask/app.py", line 1461, in dispatch_request
    return self.view_functions[rule.endpoint](**req.view_args)
  File "parser.py", line 95, in convert
    rendered_jinja2_tpl = jinja2_tpl.render(values)
  File "/home/django/.local/share/virtualenvs/flask-backend-4nHDySRL/lib/python3.6/site-packages/jinja2/environment.py", line 969, in render
    return self.environment.handle_exception(exc_info, True)
  File "/home/django/.local/share/virtualenvs/flask-backend-4nHDySRL/lib/python3.6/site-packages/jinja2/environment.py", line 742, in handle_exception
    reraise(exc_type, exc_value, tb)
  File "/home/django/.local/share/virtualenvs/flask-backend-4nHDySRL/lib/python3.6/site-packages/jinja2/_compat.py", line 36, in reraise
    raise value.with_traceback(tb)
  File "<template>", line 1, in <module>
AttributeError: 'str' object has no attribute '__call__'
2019-02-17 22:59:13,510 - __main__ - ERROR - Exception on /convert [POST]
Traceback (most recent call last):
  File "/home/django/.local/share/virtualenvs/flask-backend-4nHDySRL/lib/python3.6/site-packages/flask/app.py", line 1817, in wsgi_app
    response = self.full_dispatch_request()
  File "/home/django/.local/share/virtualenvs/flask-backend-4nHDySRL/lib/python3.6/site-packages/flask/app.py", line 1477, in full_dispatch_request
    rv = self.handle_user_exception(e)
  File "/home/django/.local/share/virtualenvs/flask-backend-4nHDySRL/lib/python3.6/site-packages/flask_cors/extension.py", line 161, in wrapped_function
    return cors_after_request(app.make_response(f(*args, **kwargs)))
  File "/home/django/.local/share/virtualenvs/flask-backend-4nHDySRL/lib/python3.6/site-packages/flask/app.py", line 1381, in handle_user_exception
    reraise(exc_type, exc_value, tb)
  File "/home/django/.local/share/virtualenvs/flask-backend-4nHDySRL/lib/python3.6/site-packages/flask/_compat.py", line 33, in reraise
    raise value
  File "/home/django/.local/share/virtualenvs/flask-backend-4nHDySRL/lib/python3.6/site-packages/flask/app.py", line 1475, in full_dispatch_request
    rv = self.dispatch_request()
  File "/home/django/.local/share/virtualenvs/flask-backend-4nHDySRL/lib/python3.6/site-packages/flask/app.py", line 1461, in dispatch_request
    return self.view_functions[rule.endpoint](**req.view_args)
  File "parser.py", line 95, in convert
    rendered_jinja2_tpl = jinja2_tpl.render(values)
  File "/home/django/.local/share/virtualenvs/flask-backend-4nHDySRL/lib/python3.6/site-packages/jinja2/environment.py", line 969, in render
    return self.environment.handle_exception(exc_info, True)
  File "/home/django/.local/share/virtualenvs/flask-backend-4nHDySRL/lib/python3.6/site-packages/jinja2/environment.py", line 742, in handle_exception
    reraise(exc_type, exc_value, tb)
  File "/home/django/.local/share/virtualenvs/flask-backend-4nHDySRL/lib/python3.6/site-packages/jinja2/_compat.py", line 36, in reraise
    raise value.with_traceback(tb)
  File "<template>", line 1, in <module>
AttributeError: 'str' object has no attribute '__call__'
2019-02-17 22:59:52,982 - __main__ - ERROR - Exception on /convert [POST]
Traceback (most recent call last):
  File "/home/django/.local/share/virtualenvs/flask-backend-4nHDySRL/lib/python3.6/site-packages/flask/app.py", line 1817, in wsgi_app
    response = self.full_dispatch_request()
  File "/home/django/.local/share/virtualenvs/flask-backend-4nHDySRL/lib/python3.6/site-packages/flask/app.py", line 1477, in full_dispatch_request
    rv = self.handle_user_exception(e)
  File "/home/django/.local/share/virtualenvs/flask-backend-4nHDySRL/lib/python3.6/site-packages/flask_cors/extension.py", line 161, in wrapped_function
    return cors_after_request(app.make_response(f(*args, **kwargs)))
  File "/home/django/.local/share/virtualenvs/flask-backend-4nHDySRL/lib/python3.6/site-packages/flask/app.py", line 1381, in handle_user_exception
    reraise(exc_type, exc_value, tb)
  File "/home/django/.local/share/virtualenvs/flask-backend-4nHDySRL/lib/python3.6/site-packages/flask/_compat.py", line 33, in reraise
    raise value
  File "/home/django/.local/share/virtualenvs/flask-backend-4nHDySRL/lib/python3.6/site-packages/flask/app.py", line 1475, in full_dispatch_request
    rv = self.dispatch_request()
  File "/home/django/.local/share/virtualenvs/flask-backend-4nHDySRL/lib/python3.6/site-packages/flask/app.py", line 1461, in dispatch_request
    return self.view_functions[rule.endpoint](**req.view_args)
  File "parser.py", line 95, in convert
    rendered_jinja2_tpl = jinja2_tpl.render(values)
  File "/home/django/.local/share/virtualenvs/flask-backend-4nHDySRL/lib/python3.6/site-packages/jinja2/environment.py", line 969, in render
    return self.environment.handle_exception(exc_info, True)
  File "/home/django/.local/share/virtualenvs/flask-backend-4nHDySRL/lib/python3.6/site-packages/jinja2/environment.py", line 742, in handle_exception
    reraise(exc_type, exc_value, tb)
  File "/home/django/.local/share/virtualenvs/flask-backend-4nHDySRL/lib/python3.6/site-packages/jinja2/_compat.py", line 36, in reraise
    raise value.with_traceback(tb)
  File "<template>", line 1, in <module>
AttributeError: 'str' object has no attribute '__call__'
2019-02-17 23:00:19,570 - __main__ - ERROR - Exception on /convert [POST]
Traceback (most recent call last):
  File "/home/django/.local/share/virtualenvs/flask-backend-4nHDySRL/lib/python3.6/site-packages/flask/app.py", line 1817, in wsgi_app
    response = self.full_dispatch_request()
  File "/home/django/.local/share/virtualenvs/flask-backend-4nHDySRL/lib/python3.6/site-packages/flask/app.py", line 1477, in full_dispatch_request
    rv = self.handle_user_exception(e)
  File "/home/django/.local/share/virtualenvs/flask-backend-4nHDySRL/lib/python3.6/site-packages/flask_cors/extension.py", line 161, in wrapped_function
    return cors_after_request(app.make_response(f(*args, **kwargs)))
  File "/home/django/.local/share/virtualenvs/flask-backend-4nHDySRL/lib/python3.6/site-packages/flask/app.py", line 1381, in handle_user_exception
    reraise(exc_type, exc_value, tb)
  File "/home/django/.local/share/virtualenvs/flask-backend-4nHDySRL/lib/python3.6/site-packages/flask/_compat.py", line 33, in reraise
    raise value
  File "/home/django/.local/share/virtualenvs/flask-backend-4nHDySRL/lib/python3.6/site-packages/flask/app.py", line 1475, in full_dispatch_request
    rv = self.dispatch_request()
  File "/home/django/.local/share/virtualenvs/flask-backend-4nHDySRL/lib/python3.6/site-packages/flask/app.py", line 1461, in dispatch_request
    return self.view_functions[rule.endpoint](**req.view_args)
  File "parser.py", line 95, in convert
    try:
  File "/home/django/.local/share/virtualenvs/flask-backend-4nHDySRL/lib/python3.6/site-packages/jinja2/environment.py", line 969, in render
    return self.environment.handle_exception(exc_info, True)
  File "/home/django/.local/share/virtualenvs/flask-backend-4nHDySRL/lib/python3.6/site-packages/jinja2/environment.py", line 742, in handle_exception
    reraise(exc_type, exc_value, tb)
  File "/home/django/.local/share/virtualenvs/flask-backend-4nHDySRL/lib/python3.6/site-packages/jinja2/_compat.py", line 36, in reraise
    raise value.with_traceback(tb)
  File "<template>", line 1, in <module>
AttributeError: 'str' object has no attribute '__call__'
2019-02-17 23:00:40,472 - __main__ - ERROR - Exception on /convert [POST]
Traceback (most recent call last):
  File "/home/django/.local/share/virtualenvs/flask-backend-4nHDySRL/lib/python3.6/site-packages/flask/app.py", line 1817, in wsgi_app
    response = self.full_dispatch_request()
  File "/home/django/.local/share/virtualenvs/flask-backend-4nHDySRL/lib/python3.6/site-packages/flask/app.py", line 1477, in full_dispatch_request
    rv = self.handle_user_exception(e)
  File "/home/django/.local/share/virtualenvs/flask-backend-4nHDySRL/lib/python3.6/site-packages/flask_cors/extension.py", line 161, in wrapped_function
    return cors_after_request(app.make_response(f(*args, **kwargs)))
  File "/home/django/.local/share/virtualenvs/flask-backend-4nHDySRL/lib/python3.6/site-packages/flask/app.py", line 1381, in handle_user_exception
    reraise(exc_type, exc_value, tb)
  File "/home/django/.local/share/virtualenvs/flask-backend-4nHDySRL/lib/python3.6/site-packages/flask/_compat.py", line 33, in reraise
    raise value
  File "/home/django/.local/share/virtualenvs/flask-backend-4nHDySRL/lib/python3.6/site-packages/flask/app.py", line 1475, in full_dispatch_request
    rv = self.dispatch_request()
  File "/home/django/.local/share/virtualenvs/flask-backend-4nHDySRL/lib/python3.6/site-packages/flask/app.py", line 1461, in dispatch_request
    return self.view_functions[rule.endpoint](**req.view_args)
  File "parser.py", line 96, in convert
    rendered_jinja2_tpl = jinja2_tpl.render(values)
  File "/home/django/.local/share/virtualenvs/flask-backend-4nHDySRL/lib/python3.6/site-packages/jinja2/environment.py", line 969, in render
    return self.environment.handle_exception(exc_info, True)
  File "/home/django/.local/share/virtualenvs/flask-backend-4nHDySRL/lib/python3.6/site-packages/jinja2/environment.py", line 742, in handle_exception
    reraise(exc_type, exc_value, tb)
  File "/home/django/.local/share/virtualenvs/flask-backend-4nHDySRL/lib/python3.6/site-packages/jinja2/_compat.py", line 36, in reraise
    raise value.with_traceback(tb)
  File "<template>", line 1, in <module>
AttributeError: 'str' object has no attribute '__call__'
2019-02-17 23:01:24,804 - __main__ - ERROR - Exception on /convert [POST]
Traceback (most recent call last):
  File "/home/django/.local/share/virtualenvs/flask-backend-4nHDySRL/lib/python3.6/site-packages/flask/app.py", line 1817, in wsgi_app
    response = self.full_dispatch_request()
  File "/home/django/.local/share/virtualenvs/flask-backend-4nHDySRL/lib/python3.6/site-packages/flask/app.py", line 1477, in full_dispatch_request
    rv = self.handle_user_exception(e)
  File "/home/django/.local/share/virtualenvs/flask-backend-4nHDySRL/lib/python3.6/site-packages/flask_cors/extension.py", line 161, in wrapped_function
    return cors_after_request(app.make_response(f(*args, **kwargs)))
  File "/home/django/.local/share/virtualenvs/flask-backend-4nHDySRL/lib/python3.6/site-packages/flask/app.py", line 1381, in handle_user_exception
    reraise(exc_type, exc_value, tb)
  File "/home/django/.local/share/virtualenvs/flask-backend-4nHDySRL/lib/python3.6/site-packages/flask/_compat.py", line 33, in reraise
    raise value
  File "/home/django/.local/share/virtualenvs/flask-backend-4nHDySRL/lib/python3.6/site-packages/flask/app.py", line 1475, in full_dispatch_request
    rv = self.dispatch_request()
  File "/home/django/.local/share/virtualenvs/flask-backend-4nHDySRL/lib/python3.6/site-packages/flask/app.py", line 1461, in dispatch_request
    return self.view_functions[rule.endpoint](**req.view_args)
  File "parser.py", line 97, in convert
    rendered_jinja2_tpl = jinja2_tpl.render(values)
  File "/home/django/.local/share/virtualenvs/flask-backend-4nHDySRL/lib/python3.6/site-packages/jinja2/environment.py", line 969, in render
    return self.environment.handle_exception(exc_info, True)
  File "/home/django/.local/share/virtualenvs/flask-backend-4nHDySRL/lib/python3.6/site-packages/jinja2/environment.py", line 742, in handle_exception
    reraise(exc_type, exc_value, tb)
  File "/home/django/.local/share/virtualenvs/flask-backend-4nHDySRL/lib/python3.6/site-packages/jinja2/_compat.py", line 36, in reraise
    raise value.with_traceback(tb)
  File "<template>", line 1, in <module>
AttributeError: 'str' object has no attribute '__call__'
2019-02-17 23:01:25,090 - __main__ - ERROR - Exception on /convert [POST]
Traceback (most recent call last):
  File "/home/django/.local/share/virtualenvs/flask-backend-4nHDySRL/lib/python3.6/site-packages/flask/app.py", line 1817, in wsgi_app
    response = self.full_dispatch_request()
  File "/home/django/.local/share/virtualenvs/flask-backend-4nHDySRL/lib/python3.6/site-packages/flask/app.py", line 1477, in full_dispatch_request
    rv = self.handle_user_exception(e)
  File "/home/django/.local/share/virtualenvs/flask-backend-4nHDySRL/lib/python3.6/site-packages/flask_cors/extension.py", line 161, in wrapped_function
    return cors_after_request(app.make_response(f(*args, **kwargs)))
  File "/home/django/.local/share/virtualenvs/flask-backend-4nHDySRL/lib/python3.6/site-packages/flask/app.py", line 1381, in handle_user_exception
    reraise(exc_type, exc_value, tb)
  File "/home/django/.local/share/virtualenvs/flask-backend-4nHDySRL/lib/python3.6/site-packages/flask/_compat.py", line 33, in reraise
    raise value
  File "/home/django/.local/share/virtualenvs/flask-backend-4nHDySRL/lib/python3.6/site-packages/flask/app.py", line 1475, in full_dispatch_request
    rv = self.dispatch_request()
  File "/home/django/.local/share/virtualenvs/flask-backend-4nHDySRL/lib/python3.6/site-packages/flask/app.py", line 1461, in dispatch_request
    return self.view_functions[rule.endpoint](**req.view_args)
  File "parser.py", line 97, in convert
    rendered_jinja2_tpl = jinja2_tpl.render(values)
  File "/home/django/.local/share/virtualenvs/flask-backend-4nHDySRL/lib/python3.6/site-packages/jinja2/environment.py", line 969, in render
    return self.environment.handle_exception(exc_info, True)
  File "/home/django/.local/share/virtualenvs/flask-backend-4nHDySRL/lib/python3.6/site-packages/jinja2/environment.py", line 742, in handle_exception
    reraise(exc_type, exc_value, tb)
  File "/home/django/.local/share/virtualenvs/flask-backend-4nHDySRL/lib/python3.6/site-packages/jinja2/_compat.py", line 36, in reraise
    raise value.with_traceback(tb)
  File "<template>", line 1, in <module>
AttributeError: 'str' object has no attribute '__call__'
2019-02-17 23:02:01,958 - __main__ - ERROR - Exception on /convert [POST]
Traceback (most recent call last):
  File "/home/django/.local/share/virtualenvs/flask-backend-4nHDySRL/lib/python3.6/site-packages/flask/app.py", line 1817, in wsgi_app
    response = self.full_dispatch_request()
  File "/home/django/.local/share/virtualenvs/flask-backend-4nHDySRL/lib/python3.6/site-packages/flask/app.py", line 1477, in full_dispatch_request
    rv = self.handle_user_exception(e)
  File "/home/django/.local/share/virtualenvs/flask-backend-4nHDySRL/lib/python3.6/site-packages/flask_cors/extension.py", line 161, in wrapped_function
    return cors_after_request(app.make_response(f(*args, **kwargs)))
  File "/home/django/.local/share/virtualenvs/flask-backend-4nHDySRL/lib/python3.6/site-packages/flask/app.py", line 1381, in handle_user_exception
    reraise(exc_type, exc_value, tb)
  File "/home/django/.local/share/virtualenvs/flask-backend-4nHDySRL/lib/python3.6/site-packages/flask/_compat.py", line 33, in reraise
    raise value
  File "/home/django/.local/share/virtualenvs/flask-backend-4nHDySRL/lib/python3.6/site-packages/flask/app.py", line 1475, in full_dispatch_request
    rv = self.dispatch_request()
  File "/home/django/.local/share/virtualenvs/flask-backend-4nHDySRL/lib/python3.6/site-packages/flask/app.py", line 1461, in dispatch_request
    return self.view_functions[rule.endpoint](**req.view_args)
  File "parser.py", line 98, in convert
    rendered_jinja2_tpl = jinja2_tpl.render(values)
  File "/home/django/.local/share/virtualenvs/flask-backend-4nHDySRL/lib/python3.6/site-packages/jinja2/environment.py", line 969, in render
    return self.environment.handle_exception(exc_info, True)
  File "/home/django/.local/share/virtualenvs/flask-backend-4nHDySRL/lib/python3.6/site-packages/jinja2/environment.py", line 742, in handle_exception
    reraise(exc_type, exc_value, tb)
  File "/home/django/.local/share/virtualenvs/flask-backend-4nHDySRL/lib/python3.6/site-packages/jinja2/_compat.py", line 36, in reraise
    raise value.with_traceback(tb)
  File "<template>", line 1, in <module>
AttributeError: 'str' object has no attribute '__call__'
2019-02-17 23:02:48,704 - __main__ - ERROR - Exception on /convert [POST]
Traceback (most recent call last):
  File "/home/django/.local/share/virtualenvs/flask-backend-4nHDySRL/lib/python3.6/site-packages/flask/app.py", line 1817, in wsgi_app
    response = self.full_dispatch_request()
  File "/home/django/.local/share/virtualenvs/flask-backend-4nHDySRL/lib/python3.6/site-packages/flask/app.py", line 1477, in full_dispatch_request
    rv = self.handle_user_exception(e)
  File "/home/django/.local/share/virtualenvs/flask-backend-4nHDySRL/lib/python3.6/site-packages/flask_cors/extension.py", line 161, in wrapped_function
    return cors_after_request(app.make_response(f(*args, **kwargs)))
  File "/home/django/.local/share/virtualenvs/flask-backend-4nHDySRL/lib/python3.6/site-packages/flask/app.py", line 1381, in handle_user_exception
    reraise(exc_type, exc_value, tb)
  File "/home/django/.local/share/virtualenvs/flask-backend-4nHDySRL/lib/python3.6/site-packages/flask/_compat.py", line 33, in reraise
    raise value
  File "/home/django/.local/share/virtualenvs/flask-backend-4nHDySRL/lib/python3.6/site-packages/flask/app.py", line 1475, in full_dispatch_request
    rv = self.dispatch_request()
  File "/home/django/.local/share/virtualenvs/flask-backend-4nHDySRL/lib/python3.6/site-packages/flask/app.py", line 1461, in dispatch_request
    return self.view_functions[rule.endpoint](**req.view_args)
  File "parser.py", line 100, in convert
    rendered_jinja2_tpl = jinja2_tpl.render(values)
  File "/home/django/.local/share/virtualenvs/flask-backend-4nHDySRL/lib/python3.6/site-packages/jinja2/environment.py", line 969, in render
    return self.environment.handle_exception(exc_info, True)
  File "/home/django/.local/share/virtualenvs/flask-backend-4nHDySRL/lib/python3.6/site-packages/jinja2/environment.py", line 742, in handle_exception
    reraise(exc_type, exc_value, tb)
  File "/home/django/.local/share/virtualenvs/flask-backend-4nHDySRL/lib/python3.6/site-packages/jinja2/_compat.py", line 36, in reraise
    raise value.with_traceback(tb)
  File "<template>", line 1, in <module>
AttributeError: 'str' object has no attribute '__call__'
2019-02-17 23:03:10,361 - __main__ - ERROR - Exception on /convert [POST]
Traceback (most recent call last):
  File "/home/django/.local/share/virtualenvs/flask-backend-4nHDySRL/lib/python3.6/site-packages/flask/app.py", line 1817, in wsgi_app
    response = self.full_dispatch_request()
  File "/home/django/.local/share/virtualenvs/flask-backend-4nHDySRL/lib/python3.6/site-packages/flask/app.py", line 1477, in full_dispatch_request
    rv = self.handle_user_exception(e)
  File "/home/django/.local/share/virtualenvs/flask-backend-4nHDySRL/lib/python3.6/site-packages/flask_cors/extension.py", line 161, in wrapped_function
    return cors_after_request(app.make_response(f(*args, **kwargs)))
  File "/home/django/.local/share/virtualenvs/flask-backend-4nHDySRL/lib/python3.6/site-packages/flask/app.py", line 1381, in handle_user_exception
    reraise(exc_type, exc_value, tb)
  File "/home/django/.local/share/virtualenvs/flask-backend-4nHDySRL/lib/python3.6/site-packages/flask/_compat.py", line 33, in reraise
    raise value
  File "/home/django/.local/share/virtualenvs/flask-backend-4nHDySRL/lib/python3.6/site-packages/flask/app.py", line 1475, in full_dispatch_request
    rv = self.dispatch_request()
  File "/home/django/.local/share/virtualenvs/flask-backend-4nHDySRL/lib/python3.6/site-packages/flask/app.py", line 1461, in dispatch_request
    return self.view_functions[rule.endpoint](**req.view_args)
  File "parser.py", line 100, in convert
    rendered_jinja2_tpl = jinja2_tpl.render(values)
  File "/home/django/.local/share/virtualenvs/flask-backend-4nHDySRL/lib/python3.6/site-packages/jinja2/environment.py", line 969, in render
    return self.environment.handle_exception(exc_info, True)
  File "/home/django/.local/share/virtualenvs/flask-backend-4nHDySRL/lib/python3.6/site-packages/jinja2/environment.py", line 742, in handle_exception
    reraise(exc_type, exc_value, tb)
  File "/home/django/.local/share/virtualenvs/flask-backend-4nHDySRL/lib/python3.6/site-packages/jinja2/_compat.py", line 36, in reraise
    raise value.with_traceback(tb)
  File "<template>", line 1, in <module>
AttributeError: 'str' object has no attribute '__call__'
2019-02-18 02:00:51,261 - __main__ - ERROR - Exception on /convert [POST]
Traceback (most recent call last):
  File "/home/django/.local/share/virtualenvs/flask-backend-4nHDySRL/lib/python3.6/site-packages/flask/app.py", line 1817, in wsgi_app
    response = self.full_dispatch_request()
  File "/home/django/.local/share/virtualenvs/flask-backend-4nHDySRL/lib/python3.6/site-packages/flask/app.py", line 1477, in full_dispatch_request
    rv = self.handle_user_exception(e)
  File "/home/django/.local/share/virtualenvs/flask-backend-4nHDySRL/lib/python3.6/site-packages/flask_cors/extension.py", line 161, in wrapped_function
    return cors_after_request(app.make_response(f(*args, **kwargs)))
  File "/home/django/.local/share/virtualenvs/flask-backend-4nHDySRL/lib/python3.6/site-packages/flask/app.py", line 1381, in handle_user_exception
    reraise(exc_type, exc_value, tb)
  File "/home/django/.local/share/virtualenvs/flask-backend-4nHDySRL/lib/python3.6/site-packages/flask/_compat.py", line 33, in reraise
    raise value
  File "/home/django/.local/share/virtualenvs/flask-backend-4nHDySRL/lib/python3.6/site-packages/flask/app.py", line 1475, in full_dispatch_request
    rv = self.dispatch_request()
  File "/home/django/.local/share/virtualenvs/flask-backend-4nHDySRL/lib/python3.6/site-packages/flask/app.py", line 1461, in dispatch_request
    return self.view_functions[rule.endpoint](**req.view_args)
  File "parser.py", line 94, in convert
    print(value)
NameError: name 'value' is not defined
2019-02-18 02:01:03,986 - __main__ - ERROR - Exception on /convert [POST]
Traceback (most recent call last):
  File "/home/django/.local/share/virtualenvs/flask-backend-4nHDySRL/lib/python3.6/site-packages/flask/app.py", line 1817, in wsgi_app
    response = self.full_dispatch_request()
  File "/home/django/.local/share/virtualenvs/flask-backend-4nHDySRL/lib/python3.6/site-packages/flask/app.py", line 1477, in full_dispatch_request
    rv = self.handle_user_exception(e)
  File "/home/django/.local/share/virtualenvs/flask-backend-4nHDySRL/lib/python3.6/site-packages/flask_cors/extension.py", line 161, in wrapped_function
    return cors_after_request(app.make_response(f(*args, **kwargs)))
  File "/home/django/.local/share/virtualenvs/flask-backend-4nHDySRL/lib/python3.6/site-packages/flask/app.py", line 1381, in handle_user_exception
    reraise(exc_type, exc_value, tb)
  File "/home/django/.local/share/virtualenvs/flask-backend-4nHDySRL/lib/python3.6/site-packages/flask/_compat.py", line 33, in reraise
    raise value
  File "/home/django/.local/share/virtualenvs/flask-backend-4nHDySRL/lib/python3.6/site-packages/flask/app.py", line 1475, in full_dispatch_request
    rv = self.dispatch_request()
  File "/home/django/.local/share/virtualenvs/flask-backend-4nHDySRL/lib/python3.6/site-packages/flask/app.py", line 1461, in dispatch_request
    return self.view_functions[rule.endpoint](**req.view_args)
  File "parser.py", line 94, in convert
    print(value)
NameError: name 'value' is not defined
2019-02-18 02:01:14,154 - __main__ - ERROR - Exception on /convert [POST]
Traceback (most recent call last):
  File "/home/django/.local/share/virtualenvs/flask-backend-4nHDySRL/lib/python3.6/site-packages/flask/app.py", line 1817, in wsgi_app
    response = self.full_dispatch_request()
  File "/home/django/.local/share/virtualenvs/flask-backend-4nHDySRL/lib/python3.6/site-packages/flask/app.py", line 1477, in full_dispatch_request
    rv = self.handle_user_exception(e)
  File "/home/django/.local/share/virtualenvs/flask-backend-4nHDySRL/lib/python3.6/site-packages/flask_cors/extension.py", line 161, in wrapped_function
    return cors_after_request(app.make_response(f(*args, **kwargs)))
  File "/home/django/.local/share/virtualenvs/flask-backend-4nHDySRL/lib/python3.6/site-packages/flask/app.py", line 1381, in handle_user_exception
    reraise(exc_type, exc_value, tb)
  File "/home/django/.local/share/virtualenvs/flask-backend-4nHDySRL/lib/python3.6/site-packages/flask/_compat.py", line 33, in reraise
    raise value
  File "/home/django/.local/share/virtualenvs/flask-backend-4nHDySRL/lib/python3.6/site-packages/flask/app.py", line 1475, in full_dispatch_request
    rv = self.dispatch_request()
  File "/home/django/.local/share/virtualenvs/flask-backend-4nHDySRL/lib/python3.6/site-packages/flask/app.py", line 1461, in dispatch_request
    return self.view_functions[rule.endpoint](**req.view_args)
  File "parser.py", line 94, in convert
    print(value)
NameError: name 'value' is not defined
2019-02-18 02:01:23,313 - __main__ - ERROR - Exception on /convert [POST]
Traceback (most recent call last):
  File "/home/django/.local/share/virtualenvs/flask-backend-4nHDySRL/lib/python3.6/site-packages/flask/app.py", line 1817, in wsgi_app
    response = self.full_dispatch_request()
  File "/home/django/.local/share/virtualenvs/flask-backend-4nHDySRL/lib/python3.6/site-packages/flask/app.py", line 1477, in full_dispatch_request
    rv = self.handle_user_exception(e)
  File "/home/django/.local/share/virtualenvs/flask-backend-4nHDySRL/lib/python3.6/site-packages/flask_cors/extension.py", line 161, in wrapped_function
    return cors_after_request(app.make_response(f(*args, **kwargs)))
  File "/home/django/.local/share/virtualenvs/flask-backend-4nHDySRL/lib/python3.6/site-packages/flask/app.py", line 1381, in handle_user_exception
    reraise(exc_type, exc_value, tb)
  File "/home/django/.local/share/virtualenvs/flask-backend-4nHDySRL/lib/python3.6/site-packages/flask/_compat.py", line 33, in reraise
    raise value
  File "/home/django/.local/share/virtualenvs/flask-backend-4nHDySRL/lib/python3.6/site-packages/flask/app.py", line 1475, in full_dispatch_request
    rv = self.dispatch_request()
  File "/home/django/.local/share/virtualenvs/flask-backend-4nHDySRL/lib/python3.6/site-packages/flask/app.py", line 1461, in dispatch_request
    return self.view_functions[rule.endpoint](**req.view_args)
  File "parser.py", line 94, in convert
    print(value)
NameError: name 'value' is not defined
2019-02-18 02:01:26,313 - __main__ - ERROR - Exception on /convert [POST]
Traceback (most recent call last):
  File "/home/django/.local/share/virtualenvs/flask-backend-4nHDySRL/lib/python3.6/site-packages/flask/app.py", line 1817, in wsgi_app
    response = self.full_dispatch_request()
  File "/home/django/.local/share/virtualenvs/flask-backend-4nHDySRL/lib/python3.6/site-packages/flask/app.py", line 1477, in full_dispatch_request
    rv = self.handle_user_exception(e)
  File "/home/django/.local/share/virtualenvs/flask-backend-4nHDySRL/lib/python3.6/site-packages/flask_cors/extension.py", line 161, in wrapped_function
    return cors_after_request(app.make_response(f(*args, **kwargs)))
  File "/home/django/.local/share/virtualenvs/flask-backend-4nHDySRL/lib/python3.6/site-packages/flask/app.py", line 1381, in handle_user_exception
    reraise(exc_type, exc_value, tb)
  File "/home/django/.local/share/virtualenvs/flask-backend-4nHDySRL/lib/python3.6/site-packages/flask/_compat.py", line 33, in reraise
    raise value
  File "/home/django/.local/share/virtualenvs/flask-backend-4nHDySRL/lib/python3.6/site-packages/flask/app.py", line 1475, in full_dispatch_request
    rv = self.dispatch_request()
  File "/home/django/.local/share/virtualenvs/flask-backend-4nHDySRL/lib/python3.6/site-packages/flask/app.py", line 1461, in dispatch_request
    return self.view_functions[rule.endpoint](**req.view_args)
  File "parser.py", line 94, in convert
    print(value)
NameError: name 'value' is not defined
2019-02-18 02:01:54,373 - __main__ - ERROR - Exception on /convert [POST]
Traceback (most recent call last):
  File "/home/django/.local/share/virtualenvs/flask-backend-4nHDySRL/lib/python3.6/site-packages/flask/app.py", line 1817, in wsgi_app
    response = self.full_dispatch_request()
  File "/home/django/.local/share/virtualenvs/flask-backend-4nHDySRL/lib/python3.6/site-packages/flask/app.py", line 1477, in full_dispatch_request
    rv = self.handle_user_exception(e)
  File "/home/django/.local/share/virtualenvs/flask-backend-4nHDySRL/lib/python3.6/site-packages/flask_cors/extension.py", line 161, in wrapped_function
    return cors_after_request(app.make_response(f(*args, **kwargs)))
  File "/home/django/.local/share/virtualenvs/flask-backend-4nHDySRL/lib/python3.6/site-packages/flask/app.py", line 1381, in handle_user_exception
    reraise(exc_type, exc_value, tb)
  File "/home/django/.local/share/virtualenvs/flask-backend-4nHDySRL/lib/python3.6/site-packages/flask/_compat.py", line 33, in reraise
    raise value
  File "/home/django/.local/share/virtualenvs/flask-backend-4nHDySRL/lib/python3.6/site-packages/flask/app.py", line 1475, in full_dispatch_request
    rv = self.dispatch_request()
  File "/home/django/.local/share/virtualenvs/flask-backend-4nHDySRL/lib/python3.6/site-packages/flask/app.py", line 1461, in dispatch_request
    return self.view_functions[rule.endpoint](**req.view_args)
  File "parser.py", line 94, in convert
    print(value)
NameError: name 'value' is not defined
2019-02-18 02:02:03,399 - __main__ - ERROR - Exception on /convert [POST]
Traceback (most recent call last):
  File "/home/django/.local/share/virtualenvs/flask-backend-4nHDySRL/lib/python3.6/site-packages/flask/app.py", line 1817, in wsgi_app
    response = self.full_dispatch_request()
  File "/home/django/.local/share/virtualenvs/flask-backend-4nHDySRL/lib/python3.6/site-packages/flask/app.py", line 1477, in full_dispatch_request
    rv = self.handle_user_exception(e)
  File "/home/django/.local/share/virtualenvs/flask-backend-4nHDySRL/lib/python3.6/site-packages/flask_cors/extension.py", line 161, in wrapped_function
    return cors_after_request(app.make_response(f(*args, **kwargs)))
  File "/home/django/.local/share/virtualenvs/flask-backend-4nHDySRL/lib/python3.6/site-packages/flask/app.py", line 1381, in handle_user_exception
    reraise(exc_type, exc_value, tb)
  File "/home/django/.local/share/virtualenvs/flask-backend-4nHDySRL/lib/python3.6/site-packages/flask/_compat.py", line 33, in reraise
    raise value
  File "/home/django/.local/share/virtualenvs/flask-backend-4nHDySRL/lib/python3.6/site-packages/flask/app.py", line 1475, in full_dispatch_request
    rv = self.dispatch_request()
  File "/home/django/.local/share/virtualenvs/flask-backend-4nHDySRL/lib/python3.6/site-packages/flask/app.py", line 1461, in dispatch_request
    return self.view_functions[rule.endpoint](**req.view_args)
  File "parser.py", line 94, in convert
    print(value)
NameError: name 'value' is not defined
2019-02-18 02:02:04,067 - __main__ - ERROR - Exception on /convert [POST]
Traceback (most recent call last):
  File "/home/django/.local/share/virtualenvs/flask-backend-4nHDySRL/lib/python3.6/site-packages/flask/app.py", line 1817, in wsgi_app
    response = self.full_dispatch_request()
  File "/home/django/.local/share/virtualenvs/flask-backend-4nHDySRL/lib/python3.6/site-packages/flask/app.py", line 1477, in full_dispatch_request
    rv = self.handle_user_exception(e)
  File "/home/django/.local/share/virtualenvs/flask-backend-4nHDySRL/lib/python3.6/site-packages/flask_cors/extension.py", line 161, in wrapped_function
    return cors_after_request(app.make_response(f(*args, **kwargs)))
  File "/home/django/.local/share/virtualenvs/flask-backend-4nHDySRL/lib/python3.6/site-packages/flask/app.py", line 1381, in handle_user_exception
    reraise(exc_type, exc_value, tb)
  File "/home/django/.local/share/virtualenvs/flask-backend-4nHDySRL/lib/python3.6/site-packages/flask/_compat.py", line 33, in reraise
    raise value
  File "/home/django/.local/share/virtualenvs/flask-backend-4nHDySRL/lib/python3.6/site-packages/flask/app.py", line 1475, in full_dispatch_request
    rv = self.dispatch_request()
  File "/home/django/.local/share/virtualenvs/flask-backend-4nHDySRL/lib/python3.6/site-packages/flask/app.py", line 1461, in dispatch_request
    return self.view_functions[rule.endpoint](**req.view_args)
  File "parser.py", line 94, in convert
    print(value)
NameError: name 'value' is not defined
2019-02-18 02:03:15,881 - __main__ - ERROR - Exception on /convert [POST]
Traceback (most recent call last):
  File "/home/django/.local/share/virtualenvs/flask-backend-4nHDySRL/lib/python3.6/site-packages/flask/app.py", line 1817, in wsgi_app
    response = self.full_dispatch_request()
  File "/home/django/.local/share/virtualenvs/flask-backend-4nHDySRL/lib/python3.6/site-packages/flask/app.py", line 1477, in full_dispatch_request
    rv = self.handle_user_exception(e)
  File "/home/django/.local/share/virtualenvs/flask-backend-4nHDySRL/lib/python3.6/site-packages/flask_cors/extension.py", line 161, in wrapped_function
    return cors_after_request(app.make_response(f(*args, **kwargs)))
  File "/home/django/.local/share/virtualenvs/flask-backend-4nHDySRL/lib/python3.6/site-packages/flask/app.py", line 1381, in handle_user_exception
    reraise(exc_type, exc_value, tb)
  File "/home/django/.local/share/virtualenvs/flask-backend-4nHDySRL/lib/python3.6/site-packages/flask/_compat.py", line 33, in reraise
    raise value
  File "/home/django/.local/share/virtualenvs/flask-backend-4nHDySRL/lib/python3.6/site-packages/flask/app.py", line 1475, in full_dispatch_request
    rv = self.dispatch_request()
  File "/home/django/.local/share/virtualenvs/flask-backend-4nHDySRL/lib/python3.6/site-packages/flask/app.py", line 1461, in dispatch_request
    return self.view_functions[rule.endpoint](**req.view_args)
  File "parser.py", line 103, in convert
    rendered_jinja2_tpl = jinja2_tpl.render(values)
  File "/home/django/.local/share/virtualenvs/flask-backend-4nHDySRL/lib/python3.6/site-packages/jinja2/environment.py", line 969, in render
    return self.environment.handle_exception(exc_info, True)
  File "/home/django/.local/share/virtualenvs/flask-backend-4nHDySRL/lib/python3.6/site-packages/jinja2/environment.py", line 742, in handle_exception
    reraise(exc_type, exc_value, tb)
  File "/home/django/.local/share/virtualenvs/flask-backend-4nHDySRL/lib/python3.6/site-packages/jinja2/_compat.py", line 36, in reraise
    raise value.with_traceback(tb)
  File "<template>", line 1, in <module>
AttributeError: 'str' object has no attribute '__call__'
2019-02-18 02:03:33,142 - __main__ - ERROR - Exception on /convert [POST]
Traceback (most recent call last):
  File "/home/django/.local/share/virtualenvs/flask-backend-4nHDySRL/lib/python3.6/site-packages/flask/app.py", line 1817, in wsgi_app
    response = self.full_dispatch_request()
  File "/home/django/.local/share/virtualenvs/flask-backend-4nHDySRL/lib/python3.6/site-packages/flask/app.py", line 1477, in full_dispatch_request
    rv = self.handle_user_exception(e)
  File "/home/django/.local/share/virtualenvs/flask-backend-4nHDySRL/lib/python3.6/site-packages/flask_cors/extension.py", line 161, in wrapped_function
    return cors_after_request(app.make_response(f(*args, **kwargs)))
  File "/home/django/.local/share/virtualenvs/flask-backend-4nHDySRL/lib/python3.6/site-packages/flask/app.py", line 1381, in handle_user_exception
    reraise(exc_type, exc_value, tb)
  File "/home/django/.local/share/virtualenvs/flask-backend-4nHDySRL/lib/python3.6/site-packages/flask/_compat.py", line 33, in reraise
    raise value
  File "/home/django/.local/share/virtualenvs/flask-backend-4nHDySRL/lib/python3.6/site-packages/flask/app.py", line 1475, in full_dispatch_request
    rv = self.dispatch_request()
  File "/home/django/.local/share/virtualenvs/flask-backend-4nHDySRL/lib/python3.6/site-packages/flask/app.py", line 1461, in dispatch_request
    return self.view_functions[rule.endpoint](**req.view_args)
  File "parser.py", line 103, in convert
    rendered_jinja2_tpl = jinja2_tpl.render(values)
  File "/home/django/.local/share/virtualenvs/flask-backend-4nHDySRL/lib/python3.6/site-packages/jinja2/environment.py", line 969, in render
    return self.environment.handle_exception(exc_info, True)
  File "/home/django/.local/share/virtualenvs/flask-backend-4nHDySRL/lib/python3.6/site-packages/jinja2/environment.py", line 742, in handle_exception
    reraise(exc_type, exc_value, tb)
  File "/home/django/.local/share/virtualenvs/flask-backend-4nHDySRL/lib/python3.6/site-packages/jinja2/_compat.py", line 36, in reraise
    raise value.with_traceback(tb)
  File "<template>", line 1, in <module>
AttributeError: 'str' object has no attribute '__call__'
2019-02-18 02:13:39,896 - __main__ - ERROR - Exception on /convert [POST]
Traceback (most recent call last):
  File "/home/django/.local/share/virtualenvs/flask-backend-4nHDySRL/lib/python3.6/site-packages/flask/app.py", line 1817, in wsgi_app
    response = self.full_dispatch_request()
  File "/home/django/.local/share/virtualenvs/flask-backend-4nHDySRL/lib/python3.6/site-packages/flask/app.py", line 1477, in full_dispatch_request
    rv = self.handle_user_exception(e)
  File "/home/django/.local/share/virtualenvs/flask-backend-4nHDySRL/lib/python3.6/site-packages/flask_cors/extension.py", line 161, in wrapped_function
    return cors_after_request(app.make_response(f(*args, **kwargs)))
  File "/home/django/.local/share/virtualenvs/flask-backend-4nHDySRL/lib/python3.6/site-packages/flask/app.py", line 1381, in handle_user_exception
    reraise(exc_type, exc_value, tb)
  File "/home/django/.local/share/virtualenvs/flask-backend-4nHDySRL/lib/python3.6/site-packages/flask/_compat.py", line 33, in reraise
    raise value
  File "/home/django/.local/share/virtualenvs/flask-backend-4nHDySRL/lib/python3.6/site-packages/flask/app.py", line 1475, in full_dispatch_request
    rv = self.dispatch_request()
  File "/home/django/.local/share/virtualenvs/flask-backend-4nHDySRL/lib/python3.6/site-packages/flask/app.py", line 1461, in dispatch_request
    return self.view_functions[rule.endpoint](**req.view_args)
  File "parser.py", line 111, in convert
    # if bool(int(json_request['request_info']['showwhitespaces'])):
KeyError: 'showwhitespaces'
2019-02-18 02:13:40,776 - __main__ - ERROR - Exception on /convert [POST]
Traceback (most recent call last):
  File "/home/django/.local/share/virtualenvs/flask-backend-4nHDySRL/lib/python3.6/site-packages/flask/app.py", line 1817, in wsgi_app
    response = self.full_dispatch_request()
  File "/home/django/.local/share/virtualenvs/flask-backend-4nHDySRL/lib/python3.6/site-packages/flask/app.py", line 1477, in full_dispatch_request
    rv = self.handle_user_exception(e)
  File "/home/django/.local/share/virtualenvs/flask-backend-4nHDySRL/lib/python3.6/site-packages/flask_cors/extension.py", line 161, in wrapped_function
    return cors_after_request(app.make_response(f(*args, **kwargs)))
  File "/home/django/.local/share/virtualenvs/flask-backend-4nHDySRL/lib/python3.6/site-packages/flask/app.py", line 1381, in handle_user_exception
    reraise(exc_type, exc_value, tb)
  File "/home/django/.local/share/virtualenvs/flask-backend-4nHDySRL/lib/python3.6/site-packages/flask/_compat.py", line 33, in reraise
    raise value
  File "/home/django/.local/share/virtualenvs/flask-backend-4nHDySRL/lib/python3.6/site-packages/flask/app.py", line 1475, in full_dispatch_request
    rv = self.dispatch_request()
  File "/home/django/.local/share/virtualenvs/flask-backend-4nHDySRL/lib/python3.6/site-packages/flask/app.py", line 1461, in dispatch_request
    return self.view_functions[rule.endpoint](**req.view_args)
  File "parser.py", line 111, in convert
    # if bool(int(json_request['request_info']['showwhitespaces'])):
KeyError: 'showwhitespaces'
2019-02-18 02:14:12,405 - __main__ - ERROR - Exception on /convert [POST]
Traceback (most recent call last):
  File "/home/django/.local/share/virtualenvs/flask-backend-4nHDySRL/lib/python3.6/site-packages/flask/app.py", line 1817, in wsgi_app
    response = self.full_dispatch_request()
  File "/home/django/.local/share/virtualenvs/flask-backend-4nHDySRL/lib/python3.6/site-packages/flask/app.py", line 1477, in full_dispatch_request
    rv = self.handle_user_exception(e)
  File "/home/django/.local/share/virtualenvs/flask-backend-4nHDySRL/lib/python3.6/site-packages/flask_cors/extension.py", line 161, in wrapped_function
    return cors_after_request(app.make_response(f(*args, **kwargs)))
  File "/home/django/.local/share/virtualenvs/flask-backend-4nHDySRL/lib/python3.6/site-packages/flask/app.py", line 1381, in handle_user_exception
    reraise(exc_type, exc_value, tb)
  File "/home/django/.local/share/virtualenvs/flask-backend-4nHDySRL/lib/python3.6/site-packages/flask/_compat.py", line 33, in reraise
    raise value
  File "/home/django/.local/share/virtualenvs/flask-backend-4nHDySRL/lib/python3.6/site-packages/flask/app.py", line 1475, in full_dispatch_request
    rv = self.dispatch_request()
  File "/home/django/.local/share/virtualenvs/flask-backend-4nHDySRL/lib/python3.6/site-packages/flask/app.py", line 1461, in dispatch_request
    return self.view_functions[rule.endpoint](**req.view_args)
  File "parser.py", line 111, in convert
    # if bool(int(json_request['request_info']['showwhitespaces'])):
KeyError: 'showwhitespaces'
2019-02-18 02:14:13,076 - __main__ - ERROR - Exception on /convert [POST]
Traceback (most recent call last):
  File "/home/django/.local/share/virtualenvs/flask-backend-4nHDySRL/lib/python3.6/site-packages/flask/app.py", line 1817, in wsgi_app
    response = self.full_dispatch_request()
  File "/home/django/.local/share/virtualenvs/flask-backend-4nHDySRL/lib/python3.6/site-packages/flask/app.py", line 1477, in full_dispatch_request
    rv = self.handle_user_exception(e)
  File "/home/django/.local/share/virtualenvs/flask-backend-4nHDySRL/lib/python3.6/site-packages/flask_cors/extension.py", line 161, in wrapped_function
    return cors_after_request(app.make_response(f(*args, **kwargs)))
  File "/home/django/.local/share/virtualenvs/flask-backend-4nHDySRL/lib/python3.6/site-packages/flask/app.py", line 1381, in handle_user_exception
    reraise(exc_type, exc_value, tb)
  File "/home/django/.local/share/virtualenvs/flask-backend-4nHDySRL/lib/python3.6/site-packages/flask/_compat.py", line 33, in reraise
    raise value
  File "/home/django/.local/share/virtualenvs/flask-backend-4nHDySRL/lib/python3.6/site-packages/flask/app.py", line 1475, in full_dispatch_request
    rv = self.dispatch_request()
  File "/home/django/.local/share/virtualenvs/flask-backend-4nHDySRL/lib/python3.6/site-packages/flask/app.py", line 1461, in dispatch_request
    return self.view_functions[rule.endpoint](**req.view_args)
  File "parser.py", line 111, in convert
    # if bool(int(json_request['request_info']['showwhitespaces'])):
KeyError: 'showwhitespaces'
2019-02-18 02:14:16,006 - __main__ - ERROR - Exception on /convert [POST]
Traceback (most recent call last):
  File "/home/django/.local/share/virtualenvs/flask-backend-4nHDySRL/lib/python3.6/site-packages/flask/app.py", line 1817, in wsgi_app
    response = self.full_dispatch_request()
  File "/home/django/.local/share/virtualenvs/flask-backend-4nHDySRL/lib/python3.6/site-packages/flask/app.py", line 1477, in full_dispatch_request
    rv = self.handle_user_exception(e)
  File "/home/django/.local/share/virtualenvs/flask-backend-4nHDySRL/lib/python3.6/site-packages/flask_cors/extension.py", line 161, in wrapped_function
    return cors_after_request(app.make_response(f(*args, **kwargs)))
  File "/home/django/.local/share/virtualenvs/flask-backend-4nHDySRL/lib/python3.6/site-packages/flask/app.py", line 1381, in handle_user_exception
    reraise(exc_type, exc_value, tb)
  File "/home/django/.local/share/virtualenvs/flask-backend-4nHDySRL/lib/python3.6/site-packages/flask/_compat.py", line 33, in reraise
    raise value
  File "/home/django/.local/share/virtualenvs/flask-backend-4nHDySRL/lib/python3.6/site-packages/flask/app.py", line 1475, in full_dispatch_request
    rv = self.dispatch_request()
  File "/home/django/.local/share/virtualenvs/flask-backend-4nHDySRL/lib/python3.6/site-packages/flask/app.py", line 1461, in dispatch_request
    return self.view_functions[rule.endpoint](**req.view_args)
  File "parser.py", line 111, in convert
    # if bool(int(json_request['request_info']['showwhitespaces'])):
KeyError: 'showwhitespaces'
2019-02-18 02:14:20,948 - __main__ - ERROR - Exception on /convert [POST]
Traceback (most recent call last):
  File "/home/django/.local/share/virtualenvs/flask-backend-4nHDySRL/lib/python3.6/site-packages/flask/app.py", line 1817, in wsgi_app
    response = self.full_dispatch_request()
  File "/home/django/.local/share/virtualenvs/flask-backend-4nHDySRL/lib/python3.6/site-packages/flask/app.py", line 1477, in full_dispatch_request
    rv = self.handle_user_exception(e)
  File "/home/django/.local/share/virtualenvs/flask-backend-4nHDySRL/lib/python3.6/site-packages/flask_cors/extension.py", line 161, in wrapped_function
    return cors_after_request(app.make_response(f(*args, **kwargs)))
  File "/home/django/.local/share/virtualenvs/flask-backend-4nHDySRL/lib/python3.6/site-packages/flask/app.py", line 1381, in handle_user_exception
    reraise(exc_type, exc_value, tb)
  File "/home/django/.local/share/virtualenvs/flask-backend-4nHDySRL/lib/python3.6/site-packages/flask/_compat.py", line 33, in reraise
    raise value
  File "/home/django/.local/share/virtualenvs/flask-backend-4nHDySRL/lib/python3.6/site-packages/flask/app.py", line 1475, in full_dispatch_request
    rv = self.dispatch_request()
  File "/home/django/.local/share/virtualenvs/flask-backend-4nHDySRL/lib/python3.6/site-packages/flask/app.py", line 1461, in dispatch_request
    return self.view_functions[rule.endpoint](**req.view_args)
  File "parser.py", line 111, in convert
    # if bool(int(json_request['request_info']['showwhitespaces'])):
KeyError: 'showwhitespaces'
2019-02-18 02:14:40,518 - __main__ - ERROR - Exception on /convert [POST]
Traceback (most recent call last):
  File "/home/django/.local/share/virtualenvs/flask-backend-4nHDySRL/lib/python3.6/site-packages/flask/app.py", line 1817, in wsgi_app
    response = self.full_dispatch_request()
  File "/home/django/.local/share/virtualenvs/flask-backend-4nHDySRL/lib/python3.6/site-packages/flask/app.py", line 1477, in full_dispatch_request
    rv = self.handle_user_exception(e)
  File "/home/django/.local/share/virtualenvs/flask-backend-4nHDySRL/lib/python3.6/site-packages/flask_cors/extension.py", line 161, in wrapped_function
    return cors_after_request(app.make_response(f(*args, **kwargs)))
  File "/home/django/.local/share/virtualenvs/flask-backend-4nHDySRL/lib/python3.6/site-packages/flask/app.py", line 1381, in handle_user_exception
    reraise(exc_type, exc_value, tb)
  File "/home/django/.local/share/virtualenvs/flask-backend-4nHDySRL/lib/python3.6/site-packages/flask/_compat.py", line 33, in reraise
    raise value
  File "/home/django/.local/share/virtualenvs/flask-backend-4nHDySRL/lib/python3.6/site-packages/flask/app.py", line 1475, in full_dispatch_request
    rv = self.dispatch_request()
  File "/home/django/.local/share/virtualenvs/flask-backend-4nHDySRL/lib/python3.6/site-packages/flask/app.py", line 1461, in dispatch_request
    return self.view_functions[rule.endpoint](**req.view_args)
  File "parser.py", line 111, in convert
    # if bool(int(json_request['request_info']['showwhitespaces'])):
KeyError: 'showwhitespaces'
2019-02-18 02:14:44,108 - __main__ - ERROR - Exception on /convert [POST]
Traceback (most recent call last):
  File "/home/django/.local/share/virtualenvs/flask-backend-4nHDySRL/lib/python3.6/site-packages/flask/app.py", line 1817, in wsgi_app
    response = self.full_dispatch_request()
  File "/home/django/.local/share/virtualenvs/flask-backend-4nHDySRL/lib/python3.6/site-packages/flask/app.py", line 1477, in full_dispatch_request
    rv = self.handle_user_exception(e)
  File "/home/django/.local/share/virtualenvs/flask-backend-4nHDySRL/lib/python3.6/site-packages/flask_cors/extension.py", line 161, in wrapped_function
    return cors_after_request(app.make_response(f(*args, **kwargs)))
  File "/home/django/.local/share/virtualenvs/flask-backend-4nHDySRL/lib/python3.6/site-packages/flask/app.py", line 1381, in handle_user_exception
    reraise(exc_type, exc_value, tb)
  File "/home/django/.local/share/virtualenvs/flask-backend-4nHDySRL/lib/python3.6/site-packages/flask/_compat.py", line 33, in reraise
    raise value
  File "/home/django/.local/share/virtualenvs/flask-backend-4nHDySRL/lib/python3.6/site-packages/flask/app.py", line 1475, in full_dispatch_request
    rv = self.dispatch_request()
  File "/home/django/.local/share/virtualenvs/flask-backend-4nHDySRL/lib/python3.6/site-packages/flask/app.py", line 1461, in dispatch_request
    return self.view_functions[rule.endpoint](**req.view_args)
  File "parser.py", line 111, in convert
    # if bool(int(json_request['request_info']['showwhitespaces'])):
KeyError: 'showwhitespaces'
2019-02-18 02:39:14,359 - __main__ - ERROR - Exception on /convert [POST]
Traceback (most recent call last):
  File "/home/django/.local/share/virtualenvs/flask-backend-4nHDySRL/lib/python3.6/site-packages/flask/app.py", line 1817, in wsgi_app
    response = self.full_dispatch_request()
  File "/home/django/.local/share/virtualenvs/flask-backend-4nHDySRL/lib/python3.6/site-packages/flask/app.py", line 1477, in full_dispatch_request
    rv = self.handle_user_exception(e)
  File "/home/django/.local/share/virtualenvs/flask-backend-4nHDySRL/lib/python3.6/site-packages/flask_cors/extension.py", line 161, in wrapped_function
    return cors_after_request(app.make_response(f(*args, **kwargs)))
  File "/home/django/.local/share/virtualenvs/flask-backend-4nHDySRL/lib/python3.6/site-packages/flask/app.py", line 1381, in handle_user_exception
    reraise(exc_type, exc_value, tb)
  File "/home/django/.local/share/virtualenvs/flask-backend-4nHDySRL/lib/python3.6/site-packages/flask/_compat.py", line 33, in reraise
    raise value
  File "/home/django/.local/share/virtualenvs/flask-backend-4nHDySRL/lib/python3.6/site-packages/flask/app.py", line 1475, in full_dispatch_request
    rv = self.dispatch_request()
  File "/home/django/.local/share/virtualenvs/flask-backend-4nHDySRL/lib/python3.6/site-packages/flask/app.py", line 1461, in dispatch_request
    return self.view_functions[rule.endpoint](**req.view_args)
  File "parser.py", line 90, in convert
    values = dict(values)
ValueError: dictionary update sequence element #0 has length 1; 2 is required
2019-02-18 02:41:48,742 - __main__ - ERROR - Exception on /convert [POST]
Traceback (most recent call last):
  File "/home/django/.local/share/virtualenvs/flask-backend-4nHDySRL/lib/python3.6/site-packages/flask/app.py", line 1817, in wsgi_app
    response = self.full_dispatch_request()
  File "/home/django/.local/share/virtualenvs/flask-backend-4nHDySRL/lib/python3.6/site-packages/flask/app.py", line 1477, in full_dispatch_request
    rv = self.handle_user_exception(e)
  File "/home/django/.local/share/virtualenvs/flask-backend-4nHDySRL/lib/python3.6/site-packages/flask_cors/extension.py", line 161, in wrapped_function
    return cors_after_request(app.make_response(f(*args, **kwargs)))
  File "/home/django/.local/share/virtualenvs/flask-backend-4nHDySRL/lib/python3.6/site-packages/flask/app.py", line 1381, in handle_user_exception
    reraise(exc_type, exc_value, tb)
  File "/home/django/.local/share/virtualenvs/flask-backend-4nHDySRL/lib/python3.6/site-packages/flask/_compat.py", line 33, in reraise
    raise value
  File "/home/django/.local/share/virtualenvs/flask-backend-4nHDySRL/lib/python3.6/site-packages/flask/app.py", line 1475, in full_dispatch_request
    rv = self.dispatch_request()
  File "/home/django/.local/share/virtualenvs/flask-backend-4nHDySRL/lib/python3.6/site-packages/flask/app.py", line 1461, in dispatch_request
    return self.view_functions[rule.endpoint](**req.view_args)
  File "parser.py", line 90, in convert
    values = json.loads(values)[0]
KeyError: 0
2019-02-18 02:43:10,582 - __main__ - ERROR - Exception on /convert [POST]
Traceback (most recent call last):
  File "/home/django/.local/share/virtualenvs/flask-backend-4nHDySRL/lib/python3.6/site-packages/flask/app.py", line 1817, in wsgi_app
    response = self.full_dispatch_request()
  File "/home/django/.local/share/virtualenvs/flask-backend-4nHDySRL/lib/python3.6/site-packages/flask/app.py", line 1477, in full_dispatch_request
    rv = self.handle_user_exception(e)
  File "/home/django/.local/share/virtualenvs/flask-backend-4nHDySRL/lib/python3.6/site-packages/flask_cors/extension.py", line 161, in wrapped_function
    return cors_after_request(app.make_response(f(*args, **kwargs)))
  File "/home/django/.local/share/virtualenvs/flask-backend-4nHDySRL/lib/python3.6/site-packages/flask/app.py", line 1381, in handle_user_exception
    reraise(exc_type, exc_value, tb)
  File "/home/django/.local/share/virtualenvs/flask-backend-4nHDySRL/lib/python3.6/site-packages/flask/_compat.py", line 33, in reraise
    raise value
  File "/home/django/.local/share/virtualenvs/flask-backend-4nHDySRL/lib/python3.6/site-packages/flask/app.py", line 1475, in full_dispatch_request
    rv = self.dispatch_request()
  File "/home/django/.local/share/virtualenvs/flask-backend-4nHDySRL/lib/python3.6/site-packages/flask/app.py", line 1461, in dispatch_request
    return self.view_functions[rule.endpoint](**req.view_args)
  File "parser.py", line 90, in convert
    values = json.loads(values)
  File "/usr/lib/python3.6/json/__init__.py", line 354, in loads
    return _default_decoder.decode(s)
  File "/usr/lib/python3.6/json/decoder.py", line 339, in decode
    obj, end = self.raw_decode(s, idx=_w(s, 0).end())
  File "/usr/lib/python3.6/json/decoder.py", line 355, in raw_decode
    obj, end = self.scan_once(s, idx)
json.decoder.JSONDecodeError: Expecting property name enclosed in double quotes: line 2 column 5 (char 6)
2019-02-18 02:43:14,881 - __main__ - ERROR - Exception on /convert [POST]
Traceback (most recent call last):
  File "/home/django/.local/share/virtualenvs/flask-backend-4nHDySRL/lib/python3.6/site-packages/flask/app.py", line 1817, in wsgi_app
    response = self.full_dispatch_request()
  File "/home/django/.local/share/virtualenvs/flask-backend-4nHDySRL/lib/python3.6/site-packages/flask/app.py", line 1477, in full_dispatch_request
    rv = self.handle_user_exception(e)
  File "/home/django/.local/share/virtualenvs/flask-backend-4nHDySRL/lib/python3.6/site-packages/flask_cors/extension.py", line 161, in wrapped_function
    return cors_after_request(app.make_response(f(*args, **kwargs)))
  File "/home/django/.local/share/virtualenvs/flask-backend-4nHDySRL/lib/python3.6/site-packages/flask/app.py", line 1381, in handle_user_exception
    reraise(exc_type, exc_value, tb)
  File "/home/django/.local/share/virtualenvs/flask-backend-4nHDySRL/lib/python3.6/site-packages/flask/_compat.py", line 33, in reraise
    raise value
  File "/home/django/.local/share/virtualenvs/flask-backend-4nHDySRL/lib/python3.6/site-packages/flask/app.py", line 1475, in full_dispatch_request
    rv = self.dispatch_request()
  File "/home/django/.local/share/virtualenvs/flask-backend-4nHDySRL/lib/python3.6/site-packages/flask/app.py", line 1461, in dispatch_request
    return self.view_functions[rule.endpoint](**req.view_args)
  File "parser.py", line 90, in convert
    values = json.loads(values)
  File "/usr/lib/python3.6/json/__init__.py", line 354, in loads
    return _default_decoder.decode(s)
  File "/usr/lib/python3.6/json/decoder.py", line 339, in decode
    obj, end = self.raw_decode(s, idx=_w(s, 0).end())
  File "/usr/lib/python3.6/json/decoder.py", line 355, in raw_decode
    obj, end = self.scan_once(s, idx)
json.decoder.JSONDecodeError: Expecting property name enclosed in double quotes: line 2 column 5 (char 6)
2019-02-18 13:23:01,519 - __main__ - ERROR - Exception on /convert [POST]
Traceback (most recent call last):
  File "/home/django/.local/share/virtualenvs/flask-backend-4nHDySRL/lib/python3.6/site-packages/flask/app.py", line 1817, in wsgi_app
    response = self.full_dispatch_request()
  File "/home/django/.local/share/virtualenvs/flask-backend-4nHDySRL/lib/python3.6/site-packages/flask/app.py", line 1477, in full_dispatch_request
    rv = self.handle_user_exception(e)
  File "/home/django/.local/share/virtualenvs/flask-backend-4nHDySRL/lib/python3.6/site-packages/flask_cors/extension.py", line 161, in wrapped_function
    return cors_after_request(app.make_response(f(*args, **kwargs)))
  File "/home/django/.local/share/virtualenvs/flask-backend-4nHDySRL/lib/python3.6/site-packages/flask/app.py", line 1381, in handle_user_exception
    reraise(exc_type, exc_value, tb)
  File "/home/django/.local/share/virtualenvs/flask-backend-4nHDySRL/lib/python3.6/site-packages/flask/_compat.py", line 33, in reraise
    raise value
  File "/home/django/.local/share/virtualenvs/flask-backend-4nHDySRL/lib/python3.6/site-packages/flask/app.py", line 1475, in full_dispatch_request
    rv = self.dispatch_request()
  File "/home/django/.local/share/virtualenvs/flask-backend-4nHDySRL/lib/python3.6/site-packages/flask/app.py", line 1461, in dispatch_request
    return self.view_functions[rule.endpoint](**req.view_args)
  File "parser.py", line 90, in convert
    values = json.loads(values)
  File "/usr/lib/python3.6/json/__init__.py", line 354, in loads
    return _default_decoder.decode(s)
  File "/usr/lib/python3.6/json/decoder.py", line 339, in decode
    obj, end = self.raw_decode(s, idx=_w(s, 0).end())
  File "/usr/lib/python3.6/json/decoder.py", line 355, in raw_decode
    obj, end = self.scan_once(s, idx)
json.decoder.JSONDecodeError: Expecting property name enclosed in double quotes: line 1 column 2 (char 1)
2019-02-18 13:23:07,011 - __main__ - ERROR - Exception on /convert [POST]
Traceback (most recent call last):
  File "/home/django/.local/share/virtualenvs/flask-backend-4nHDySRL/lib/python3.6/site-packages/flask/app.py", line 1817, in wsgi_app
    response = self.full_dispatch_request()
  File "/home/django/.local/share/virtualenvs/flask-backend-4nHDySRL/lib/python3.6/site-packages/flask/app.py", line 1477, in full_dispatch_request
    rv = self.handle_user_exception(e)
  File "/home/django/.local/share/virtualenvs/flask-backend-4nHDySRL/lib/python3.6/site-packages/flask_cors/extension.py", line 161, in wrapped_function
    return cors_after_request(app.make_response(f(*args, **kwargs)))
  File "/home/django/.local/share/virtualenvs/flask-backend-4nHDySRL/lib/python3.6/site-packages/flask/app.py", line 1381, in handle_user_exception
    reraise(exc_type, exc_value, tb)
  File "/home/django/.local/share/virtualenvs/flask-backend-4nHDySRL/lib/python3.6/site-packages/flask/_compat.py", line 33, in reraise
    raise value
  File "/home/django/.local/share/virtualenvs/flask-backend-4nHDySRL/lib/python3.6/site-packages/flask/app.py", line 1475, in full_dispatch_request
    rv = self.dispatch_request()
  File "/home/django/.local/share/virtualenvs/flask-backend-4nHDySRL/lib/python3.6/site-packages/flask/app.py", line 1461, in dispatch_request
    return self.view_functions[rule.endpoint](**req.view_args)
  File "parser.py", line 90, in convert
    values = json.loads(values)
  File "/usr/lib/python3.6/json/__init__.py", line 354, in loads
    return _default_decoder.decode(s)
  File "/usr/lib/python3.6/json/decoder.py", line 339, in decode
    obj, end = self.raw_decode(s, idx=_w(s, 0).end())
  File "/usr/lib/python3.6/json/decoder.py", line 355, in raw_decode
    obj, end = self.scan_once(s, idx)
json.decoder.JSONDecodeError: Expecting property name enclosed in double quotes: line 1 column 2 (char 1)
2019-02-18 13:23:37,453 - __main__ - ERROR - Exception on /convert [POST]
Traceback (most recent call last):
  File "/home/django/.local/share/virtualenvs/flask-backend-4nHDySRL/lib/python3.6/site-packages/flask/app.py", line 1817, in wsgi_app
    response = self.full_dispatch_request()
  File "/home/django/.local/share/virtualenvs/flask-backend-4nHDySRL/lib/python3.6/site-packages/flask/app.py", line 1477, in full_dispatch_request
    rv = self.handle_user_exception(e)
  File "/home/django/.local/share/virtualenvs/flask-backend-4nHDySRL/lib/python3.6/site-packages/flask_cors/extension.py", line 161, in wrapped_function
    return cors_after_request(app.make_response(f(*args, **kwargs)))
  File "/home/django/.local/share/virtualenvs/flask-backend-4nHDySRL/lib/python3.6/site-packages/flask/app.py", line 1381, in handle_user_exception
    reraise(exc_type, exc_value, tb)
  File "/home/django/.local/share/virtualenvs/flask-backend-4nHDySRL/lib/python3.6/site-packages/flask/_compat.py", line 33, in reraise
    raise value
  File "/home/django/.local/share/virtualenvs/flask-backend-4nHDySRL/lib/python3.6/site-packages/flask/app.py", line 1475, in full_dispatch_request
    rv = self.dispatch_request()
  File "/home/django/.local/share/virtualenvs/flask-backend-4nHDySRL/lib/python3.6/site-packages/flask/app.py", line 1461, in dispatch_request
    return self.view_functions[rule.endpoint](**req.view_args)
  File "parser.py", line 90, in convert
    values = json.loads(values)
  File "/usr/lib/python3.6/json/__init__.py", line 354, in loads
    return _default_decoder.decode(s)
  File "/usr/lib/python3.6/json/decoder.py", line 339, in decode
    obj, end = self.raw_decode(s, idx=_w(s, 0).end())
  File "/usr/lib/python3.6/json/decoder.py", line 355, in raw_decode
    obj, end = self.scan_once(s, idx)
json.decoder.JSONDecodeError: Expecting property name enclosed in double quotes: line 1 column 2 (char 1)
2019-02-18 13:23:52,046 - __main__ - ERROR - Exception on /convert [POST]
Traceback (most recent call last):
  File "/home/django/.local/share/virtualenvs/flask-backend-4nHDySRL/lib/python3.6/site-packages/flask/app.py", line 1817, in wsgi_app
    response = self.full_dispatch_request()
  File "/home/django/.local/share/virtualenvs/flask-backend-4nHDySRL/lib/python3.6/site-packages/flask/app.py", line 1477, in full_dispatch_request
    rv = self.handle_user_exception(e)
  File "/home/django/.local/share/virtualenvs/flask-backend-4nHDySRL/lib/python3.6/site-packages/flask_cors/extension.py", line 161, in wrapped_function
    return cors_after_request(app.make_response(f(*args, **kwargs)))
  File "/home/django/.local/share/virtualenvs/flask-backend-4nHDySRL/lib/python3.6/site-packages/flask/app.py", line 1381, in handle_user_exception
    reraise(exc_type, exc_value, tb)
  File "/home/django/.local/share/virtualenvs/flask-backend-4nHDySRL/lib/python3.6/site-packages/flask/_compat.py", line 33, in reraise
    raise value
  File "/home/django/.local/share/virtualenvs/flask-backend-4nHDySRL/lib/python3.6/site-packages/flask/app.py", line 1475, in full_dispatch_request
    rv = self.dispatch_request()
  File "/home/django/.local/share/virtualenvs/flask-backend-4nHDySRL/lib/python3.6/site-packages/flask/app.py", line 1461, in dispatch_request
    return self.view_functions[rule.endpoint](**req.view_args)
  File "parser.py", line 90, in convert
    values = json.loads(values)
  File "/usr/lib/python3.6/json/__init__.py", line 354, in loads
    return _default_decoder.decode(s)
  File "/usr/lib/python3.6/json/decoder.py", line 339, in decode
    obj, end = self.raw_decode(s, idx=_w(s, 0).end())
  File "/usr/lib/python3.6/json/decoder.py", line 355, in raw_decode
    obj, end = self.scan_once(s, idx)
json.decoder.JSONDecodeError: Expecting ':' delimiter: line 1 column 5 (char 4)
2019-02-18 13:24:15,079 - __main__ - ERROR - Exception on /convert [POST]
Traceback (most recent call last):
  File "/home/django/.local/share/virtualenvs/flask-backend-4nHDySRL/lib/python3.6/site-packages/flask/app.py", line 1817, in wsgi_app
    response = self.full_dispatch_request()
  File "/home/django/.local/share/virtualenvs/flask-backend-4nHDySRL/lib/python3.6/site-packages/flask/app.py", line 1477, in full_dispatch_request
    rv = self.handle_user_exception(e)
  File "/home/django/.local/share/virtualenvs/flask-backend-4nHDySRL/lib/python3.6/site-packages/flask_cors/extension.py", line 161, in wrapped_function
    return cors_after_request(app.make_response(f(*args, **kwargs)))
  File "/home/django/.local/share/virtualenvs/flask-backend-4nHDySRL/lib/python3.6/site-packages/flask/app.py", line 1381, in handle_user_exception
    reraise(exc_type, exc_value, tb)
  File "/home/django/.local/share/virtualenvs/flask-backend-4nHDySRL/lib/python3.6/site-packages/flask/_compat.py", line 33, in reraise
    raise value
  File "/home/django/.local/share/virtualenvs/flask-backend-4nHDySRL/lib/python3.6/site-packages/flask/app.py", line 1475, in full_dispatch_request
    rv = self.dispatch_request()
  File "/home/django/.local/share/virtualenvs/flask-backend-4nHDySRL/lib/python3.6/site-packages/flask/app.py", line 1461, in dispatch_request
    return self.view_functions[rule.endpoint](**req.view_args)
  File "parser.py", line 90, in convert
    values = json.loads(values)
  File "/usr/lib/python3.6/json/__init__.py", line 354, in loads
    return _default_decoder.decode(s)
  File "/usr/lib/python3.6/json/decoder.py", line 339, in decode
    obj, end = self.raw_decode(s, idx=_w(s, 0).end())
  File "/usr/lib/python3.6/json/decoder.py", line 355, in raw_decode
    obj, end = self.scan_once(s, idx)
json.decoder.JSONDecodeError: Expecting ':' delimiter: line 1 column 5 (char 4)
2019-02-18 13:24:26,360 - __main__ - ERROR - Exception on /convert [POST]
Traceback (most recent call last):
  File "/home/django/.local/share/virtualenvs/flask-backend-4nHDySRL/lib/python3.6/site-packages/flask/app.py", line 1817, in wsgi_app
    response = self.full_dispatch_request()
  File "/home/django/.local/share/virtualenvs/flask-backend-4nHDySRL/lib/python3.6/site-packages/flask/app.py", line 1477, in full_dispatch_request
    rv = self.handle_user_exception(e)
  File "/home/django/.local/share/virtualenvs/flask-backend-4nHDySRL/lib/python3.6/site-packages/flask_cors/extension.py", line 161, in wrapped_function
    return cors_after_request(app.make_response(f(*args, **kwargs)))
  File "/home/django/.local/share/virtualenvs/flask-backend-4nHDySRL/lib/python3.6/site-packages/flask/app.py", line 1381, in handle_user_exception
    reraise(exc_type, exc_value, tb)
  File "/home/django/.local/share/virtualenvs/flask-backend-4nHDySRL/lib/python3.6/site-packages/flask/_compat.py", line 33, in reraise
    raise value
  File "/home/django/.local/share/virtualenvs/flask-backend-4nHDySRL/lib/python3.6/site-packages/flask/app.py", line 1475, in full_dispatch_request
    rv = self.dispatch_request()
  File "/home/django/.local/share/virtualenvs/flask-backend-4nHDySRL/lib/python3.6/site-packages/flask/app.py", line 1461, in dispatch_request
    return self.view_functions[rule.endpoint](**req.view_args)
  File "parser.py", line 90, in convert
    values = json.loads(values)
  File "/usr/lib/python3.6/json/__init__.py", line 354, in loads
    return _default_decoder.decode(s)
  File "/usr/lib/python3.6/json/decoder.py", line 339, in decode
    obj, end = self.raw_decode(s, idx=_w(s, 0).end())
  File "/usr/lib/python3.6/json/decoder.py", line 355, in raw_decode
    obj, end = self.scan_once(s, idx)
json.decoder.JSONDecodeError: Expecting ':' delimiter: line 1 column 5 (char 4)
2019-02-18 13:41:56,069 - __main__ - ERROR - Exception on /convert [POST]
Traceback (most recent call last):
  File "/home/django/.local/share/virtualenvs/flask-backend-4nHDySRL/lib/python3.6/site-packages/flask/app.py", line 1817, in wsgi_app
    response = self.full_dispatch_request()
  File "/home/django/.local/share/virtualenvs/flask-backend-4nHDySRL/lib/python3.6/site-packages/flask/app.py", line 1477, in full_dispatch_request
    rv = self.handle_user_exception(e)
  File "/home/django/.local/share/virtualenvs/flask-backend-4nHDySRL/lib/python3.6/site-packages/flask_cors/extension.py", line 161, in wrapped_function
    return cors_after_request(app.make_response(f(*args, **kwargs)))
  File "/home/django/.local/share/virtualenvs/flask-backend-4nHDySRL/lib/python3.6/site-packages/flask/app.py", line 1381, in handle_user_exception
    reraise(exc_type, exc_value, tb)
  File "/home/django/.local/share/virtualenvs/flask-backend-4nHDySRL/lib/python3.6/site-packages/flask/_compat.py", line 33, in reraise
    raise value
  File "/home/django/.local/share/virtualenvs/flask-backend-4nHDySRL/lib/python3.6/site-packages/flask/app.py", line 1475, in full_dispatch_request
    rv = self.dispatch_request()
  File "/home/django/.local/share/virtualenvs/flask-backend-4nHDySRL/lib/python3.6/site-packages/flask/app.py", line 1461, in dispatch_request
    return self.view_functions[rule.endpoint](**req.view_args)
  File "parser.py", line 90, in convert
    values = json.loads(values)
  File "/usr/lib/python3.6/json/__init__.py", line 354, in loads
    return _default_decoder.decode(s)
  File "/usr/lib/python3.6/json/decoder.py", line 339, in decode
    obj, end = self.raw_decode(s, idx=_w(s, 0).end())
  File "/usr/lib/python3.6/json/decoder.py", line 355, in raw_decode
    obj, end = self.scan_once(s, idx)
json.decoder.JSONDecodeError: Expecting ':' delimiter: line 1 column 5 (char 4)
2019-02-18 13:42:18,323 - __main__ - ERROR - Exception on /convert [POST]
Traceback (most recent call last):
  File "/home/django/.local/share/virtualenvs/flask-backend-4nHDySRL/lib/python3.6/site-packages/flask/app.py", line 1817, in wsgi_app
    response = self.full_dispatch_request()
  File "/home/django/.local/share/virtualenvs/flask-backend-4nHDySRL/lib/python3.6/site-packages/flask/app.py", line 1477, in full_dispatch_request
    rv = self.handle_user_exception(e)
  File "/home/django/.local/share/virtualenvs/flask-backend-4nHDySRL/lib/python3.6/site-packages/flask_cors/extension.py", line 161, in wrapped_function
    return cors_after_request(app.make_response(f(*args, **kwargs)))
  File "/home/django/.local/share/virtualenvs/flask-backend-4nHDySRL/lib/python3.6/site-packages/flask/app.py", line 1381, in handle_user_exception
    reraise(exc_type, exc_value, tb)
  File "/home/django/.local/share/virtualenvs/flask-backend-4nHDySRL/lib/python3.6/site-packages/flask/_compat.py", line 33, in reraise
    raise value
  File "/home/django/.local/share/virtualenvs/flask-backend-4nHDySRL/lib/python3.6/site-packages/flask/app.py", line 1475, in full_dispatch_request
    rv = self.dispatch_request()
  File "/home/django/.local/share/virtualenvs/flask-backend-4nHDySRL/lib/python3.6/site-packages/flask/app.py", line 1461, in dispatch_request
    return self.view_functions[rule.endpoint](**req.view_args)
  File "parser.py", line 90, in convert
    values = json.loads(values)
  File "/usr/lib/python3.6/json/__init__.py", line 354, in loads
    return _default_decoder.decode(s)
  File "/usr/lib/python3.6/json/decoder.py", line 339, in decode
    obj, end = self.raw_decode(s, idx=_w(s, 0).end())
  File "/usr/lib/python3.6/json/decoder.py", line 355, in raw_decode
    obj, end = self.scan_once(s, idx)
json.decoder.JSONDecodeError: Expecting ':' delimiter: line 1 column 5 (char 4)
2019-02-18 13:43:05,383 - __main__ - ERROR - Exception on /convert [POST]
Traceback (most recent call last):
  File "/home/django/.local/share/virtualenvs/flask-backend-4nHDySRL/lib/python3.6/site-packages/flask/app.py", line 1817, in wsgi_app
    response = self.full_dispatch_request()
  File "/home/django/.local/share/virtualenvs/flask-backend-4nHDySRL/lib/python3.6/site-packages/flask/app.py", line 1477, in full_dispatch_request
    rv = self.handle_user_exception(e)
  File "/home/django/.local/share/virtualenvs/flask-backend-4nHDySRL/lib/python3.6/site-packages/flask_cors/extension.py", line 161, in wrapped_function
    return cors_after_request(app.make_response(f(*args, **kwargs)))
  File "/home/django/.local/share/virtualenvs/flask-backend-4nHDySRL/lib/python3.6/site-packages/flask/app.py", line 1381, in handle_user_exception
    reraise(exc_type, exc_value, tb)
  File "/home/django/.local/share/virtualenvs/flask-backend-4nHDySRL/lib/python3.6/site-packages/flask/_compat.py", line 33, in reraise
    raise value
  File "/home/django/.local/share/virtualenvs/flask-backend-4nHDySRL/lib/python3.6/site-packages/flask/app.py", line 1475, in full_dispatch_request
    rv = self.dispatch_request()
  File "/home/django/.local/share/virtualenvs/flask-backend-4nHDySRL/lib/python3.6/site-packages/flask/app.py", line 1461, in dispatch_request
    return self.view_functions[rule.endpoint](**req.view_args)
  File "parser.py", line 90, in convert
    values = json.loads(values)
  File "/usr/lib/python3.6/json/__init__.py", line 354, in loads
    return _default_decoder.decode(s)
  File "/usr/lib/python3.6/json/decoder.py", line 339, in decode
    obj, end = self.raw_decode(s, idx=_w(s, 0).end())
  File "/usr/lib/python3.6/json/decoder.py", line 355, in raw_decode
    obj, end = self.scan_once(s, idx)
json.decoder.JSONDecodeError: Expecting ':' delimiter: line 1 column 5 (char 4)
2019-02-18 13:45:24,096 - __main__ - ERROR - Exception on /convert [POST]
Traceback (most recent call last):
  File "/home/django/.local/share/virtualenvs/flask-backend-4nHDySRL/lib/python3.6/site-packages/flask/app.py", line 1817, in wsgi_app
    response = self.full_dispatch_request()
  File "/home/django/.local/share/virtualenvs/flask-backend-4nHDySRL/lib/python3.6/site-packages/flask/app.py", line 1477, in full_dispatch_request
    rv = self.handle_user_exception(e)
  File "/home/django/.local/share/virtualenvs/flask-backend-4nHDySRL/lib/python3.6/site-packages/flask_cors/extension.py", line 161, in wrapped_function
    return cors_after_request(app.make_response(f(*args, **kwargs)))
  File "/home/django/.local/share/virtualenvs/flask-backend-4nHDySRL/lib/python3.6/site-packages/flask/app.py", line 1381, in handle_user_exception
    reraise(exc_type, exc_value, tb)
  File "/home/django/.local/share/virtualenvs/flask-backend-4nHDySRL/lib/python3.6/site-packages/flask/_compat.py", line 33, in reraise
    raise value
  File "/home/django/.local/share/virtualenvs/flask-backend-4nHDySRL/lib/python3.6/site-packages/flask/app.py", line 1475, in full_dispatch_request
    rv = self.dispatch_request()
  File "/home/django/.local/share/virtualenvs/flask-backend-4nHDySRL/lib/python3.6/site-packages/flask/app.py", line 1461, in dispatch_request
    return self.view_functions[rule.endpoint](**req.view_args)
  File "parser.py", line 90, in convert
    values = json.loads(values)
  File "/usr/lib/python3.6/json/__init__.py", line 354, in loads
    return _default_decoder.decode(s)
  File "/usr/lib/python3.6/json/decoder.py", line 339, in decode
    obj, end = self.raw_decode(s, idx=_w(s, 0).end())
  File "/usr/lib/python3.6/json/decoder.py", line 355, in raw_decode
    obj, end = self.scan_once(s, idx)
json.decoder.JSONDecodeError: Expecting ':' delimiter: line 1 column 5 (char 4)
2019-02-18 13:48:08,416 - __main__ - ERROR - Exception on /convert [POST]
Traceback (most recent call last):
  File "/home/django/.local/share/virtualenvs/flask-backend-4nHDySRL/lib/python3.6/site-packages/flask/app.py", line 1817, in wsgi_app
    response = self.full_dispatch_request()
  File "/home/django/.local/share/virtualenvs/flask-backend-4nHDySRL/lib/python3.6/site-packages/flask/app.py", line 1477, in full_dispatch_request
    rv = self.handle_user_exception(e)
  File "/home/django/.local/share/virtualenvs/flask-backend-4nHDySRL/lib/python3.6/site-packages/flask_cors/extension.py", line 161, in wrapped_function
    return cors_after_request(app.make_response(f(*args, **kwargs)))
  File "/home/django/.local/share/virtualenvs/flask-backend-4nHDySRL/lib/python3.6/site-packages/flask/app.py", line 1381, in handle_user_exception
    reraise(exc_type, exc_value, tb)
  File "/home/django/.local/share/virtualenvs/flask-backend-4nHDySRL/lib/python3.6/site-packages/flask/_compat.py", line 33, in reraise
    raise value
  File "/home/django/.local/share/virtualenvs/flask-backend-4nHDySRL/lib/python3.6/site-packages/flask/app.py", line 1475, in full_dispatch_request
    rv = self.dispatch_request()
  File "/home/django/.local/share/virtualenvs/flask-backend-4nHDySRL/lib/python3.6/site-packages/flask/app.py", line 1461, in dispatch_request
    return self.view_functions[rule.endpoint](**req.view_args)
  File "parser.py", line 90, in convert
    values = json.loads(values)
  File "/usr/lib/python3.6/json/__init__.py", line 354, in loads
    return _default_decoder.decode(s)
  File "/usr/lib/python3.6/json/decoder.py", line 339, in decode
    obj, end = self.raw_decode(s, idx=_w(s, 0).end())
  File "/usr/lib/python3.6/json/decoder.py", line 355, in raw_decode
    obj, end = self.scan_once(s, idx)
json.decoder.JSONDecodeError: Expecting ':' delimiter: line 1 column 5 (char 4)
2019-02-18 13:48:23,258 - __main__ - ERROR - Exception on /convert [POST]
Traceback (most recent call last):
  File "/home/django/.local/share/virtualenvs/flask-backend-4nHDySRL/lib/python3.6/site-packages/flask/app.py", line 1817, in wsgi_app
    response = self.full_dispatch_request()
  File "/home/django/.local/share/virtualenvs/flask-backend-4nHDySRL/lib/python3.6/site-packages/flask/app.py", line 1477, in full_dispatch_request
    rv = self.handle_user_exception(e)
  File "/home/django/.local/share/virtualenvs/flask-backend-4nHDySRL/lib/python3.6/site-packages/flask_cors/extension.py", line 161, in wrapped_function
    return cors_after_request(app.make_response(f(*args, **kwargs)))
  File "/home/django/.local/share/virtualenvs/flask-backend-4nHDySRL/lib/python3.6/site-packages/flask/app.py", line 1381, in handle_user_exception
    reraise(exc_type, exc_value, tb)
  File "/home/django/.local/share/virtualenvs/flask-backend-4nHDySRL/lib/python3.6/site-packages/flask/_compat.py", line 33, in reraise
    raise value
  File "/home/django/.local/share/virtualenvs/flask-backend-4nHDySRL/lib/python3.6/site-packages/flask/app.py", line 1475, in full_dispatch_request
    rv = self.dispatch_request()
  File "/home/django/.local/share/virtualenvs/flask-backend-4nHDySRL/lib/python3.6/site-packages/flask/app.py", line 1461, in dispatch_request
    return self.view_functions[rule.endpoint](**req.view_args)
  File "parser.py", line 90, in convert
    values = json.loads(values)
  File "/usr/lib/python3.6/json/__init__.py", line 354, in loads
    return _default_decoder.decode(s)
  File "/usr/lib/python3.6/json/decoder.py", line 339, in decode
    obj, end = self.raw_decode(s, idx=_w(s, 0).end())
  File "/usr/lib/python3.6/json/decoder.py", line 357, in raw_decode
    raise JSONDecodeError("Expecting value", s, err.value) from None
json.decoder.JSONDecodeError: Expecting value: line 1 column 1 (char 0)
2019-02-18 13:48:35,663 - __main__ - ERROR - Exception on /convert [POST]
Traceback (most recent call last):
  File "/home/django/.local/share/virtualenvs/flask-backend-4nHDySRL/lib/python3.6/site-packages/flask/app.py", line 1817, in wsgi_app
    response = self.full_dispatch_request()
  File "/home/django/.local/share/virtualenvs/flask-backend-4nHDySRL/lib/python3.6/site-packages/flask/app.py", line 1477, in full_dispatch_request
    rv = self.handle_user_exception(e)
  File "/home/django/.local/share/virtualenvs/flask-backend-4nHDySRL/lib/python3.6/site-packages/flask_cors/extension.py", line 161, in wrapped_function
    return cors_after_request(app.make_response(f(*args, **kwargs)))
  File "/home/django/.local/share/virtualenvs/flask-backend-4nHDySRL/lib/python3.6/site-packages/flask/app.py", line 1381, in handle_user_exception
    reraise(exc_type, exc_value, tb)
  File "/home/django/.local/share/virtualenvs/flask-backend-4nHDySRL/lib/python3.6/site-packages/flask/_compat.py", line 33, in reraise
    raise value
  File "/home/django/.local/share/virtualenvs/flask-backend-4nHDySRL/lib/python3.6/site-packages/flask/app.py", line 1475, in full_dispatch_request
    rv = self.dispatch_request()
  File "/home/django/.local/share/virtualenvs/flask-backend-4nHDySRL/lib/python3.6/site-packages/flask/app.py", line 1461, in dispatch_request
    return self.view_functions[rule.endpoint](**req.view_args)
  File "parser.py", line 90, in convert
    values = json.loads(values)
  File "/usr/lib/python3.6/json/__init__.py", line 354, in loads
    return _default_decoder.decode(s)
  File "/usr/lib/python3.6/json/decoder.py", line 339, in decode
    obj, end = self.raw_decode(s, idx=_w(s, 0).end())
  File "/usr/lib/python3.6/json/decoder.py", line 355, in raw_decode
    obj, end = self.scan_once(s, idx)
json.decoder.JSONDecodeError: Expecting ':' delimiter: line 1 column 5 (char 4)
2019-02-18 13:52:09,866 - __main__ - ERROR - Exception on /convert [POST]
Traceback (most recent call last):
  File "/home/django/.local/share/virtualenvs/flask-backend-4nHDySRL/lib/python3.6/site-packages/flask/app.py", line 1817, in wsgi_app
    response = self.full_dispatch_request()
  File "/home/django/.local/share/virtualenvs/flask-backend-4nHDySRL/lib/python3.6/site-packages/flask/app.py", line 1477, in full_dispatch_request
    rv = self.handle_user_exception(e)
  File "/home/django/.local/share/virtualenvs/flask-backend-4nHDySRL/lib/python3.6/site-packages/flask_cors/extension.py", line 161, in wrapped_function
    return cors_after_request(app.make_response(f(*args, **kwargs)))
  File "/home/django/.local/share/virtualenvs/flask-backend-4nHDySRL/lib/python3.6/site-packages/flask/app.py", line 1381, in handle_user_exception
    reraise(exc_type, exc_value, tb)
  File "/home/django/.local/share/virtualenvs/flask-backend-4nHDySRL/lib/python3.6/site-packages/flask/_compat.py", line 33, in reraise
    raise value
  File "/home/django/.local/share/virtualenvs/flask-backend-4nHDySRL/lib/python3.6/site-packages/flask/app.py", line 1475, in full_dispatch_request
    rv = self.dispatch_request()
  File "/home/django/.local/share/virtualenvs/flask-backend-4nHDySRL/lib/python3.6/site-packages/flask/app.py", line 1461, in dispatch_request
    return self.view_functions[rule.endpoint](**req.view_args)
  File "parser.py", line 90, in convert
    values = json.loads(values)
  File "/usr/lib/python3.6/json/__init__.py", line 354, in loads
    return _default_decoder.decode(s)
  File "/usr/lib/python3.6/json/decoder.py", line 339, in decode
    obj, end = self.raw_decode(s, idx=_w(s, 0).end())
  File "/usr/lib/python3.6/json/decoder.py", line 355, in raw_decode
    obj, end = self.scan_once(s, idx)
json.decoder.JSONDecodeError: Expecting ':' delimiter: line 1 column 5 (char 4)
2019-02-18 13:52:34,712 - __main__ - ERROR - Exception on /convert [POST]
Traceback (most recent call last):
  File "/home/django/.local/share/virtualenvs/flask-backend-4nHDySRL/lib/python3.6/site-packages/flask/app.py", line 1817, in wsgi_app
    response = self.full_dispatch_request()
  File "/home/django/.local/share/virtualenvs/flask-backend-4nHDySRL/lib/python3.6/site-packages/flask/app.py", line 1477, in full_dispatch_request
    rv = self.handle_user_exception(e)
  File "/home/django/.local/share/virtualenvs/flask-backend-4nHDySRL/lib/python3.6/site-packages/flask_cors/extension.py", line 161, in wrapped_function
    return cors_after_request(app.make_response(f(*args, **kwargs)))
  File "/home/django/.local/share/virtualenvs/flask-backend-4nHDySRL/lib/python3.6/site-packages/flask/app.py", line 1381, in handle_user_exception
    reraise(exc_type, exc_value, tb)
  File "/home/django/.local/share/virtualenvs/flask-backend-4nHDySRL/lib/python3.6/site-packages/flask/_compat.py", line 33, in reraise
    raise value
  File "/home/django/.local/share/virtualenvs/flask-backend-4nHDySRL/lib/python3.6/site-packages/flask/app.py", line 1475, in full_dispatch_request
    rv = self.dispatch_request()
  File "/home/django/.local/share/virtualenvs/flask-backend-4nHDySRL/lib/python3.6/site-packages/flask/app.py", line 1461, in dispatch_request
    return self.view_functions[rule.endpoint](**req.view_args)
  File "parser.py", line 90, in convert
    values = json.loads(values)
  File "/usr/lib/python3.6/json/__init__.py", line 354, in loads
    return _default_decoder.decode(s)
  File "/usr/lib/python3.6/json/decoder.py", line 339, in decode
    obj, end = self.raw_decode(s, idx=_w(s, 0).end())
  File "/usr/lib/python3.6/json/decoder.py", line 355, in raw_decode
    obj, end = self.scan_once(s, idx)
json.decoder.JSONDecodeError: Expecting ':' delimiter: line 1 column 5 (char 4)
2019-02-18 13:53:02,799 - __main__ - ERROR - Exception on /convert [POST]
Traceback (most recent call last):
  File "/home/django/.local/share/virtualenvs/flask-backend-4nHDySRL/lib/python3.6/site-packages/flask/app.py", line 1817, in wsgi_app
    response = self.full_dispatch_request()
  File "/home/django/.local/share/virtualenvs/flask-backend-4nHDySRL/lib/python3.6/site-packages/flask/app.py", line 1477, in full_dispatch_request
    rv = self.handle_user_exception(e)
  File "/home/django/.local/share/virtualenvs/flask-backend-4nHDySRL/lib/python3.6/site-packages/flask_cors/extension.py", line 161, in wrapped_function
    return cors_after_request(app.make_response(f(*args, **kwargs)))
  File "/home/django/.local/share/virtualenvs/flask-backend-4nHDySRL/lib/python3.6/site-packages/flask/app.py", line 1381, in handle_user_exception
    reraise(exc_type, exc_value, tb)
  File "/home/django/.local/share/virtualenvs/flask-backend-4nHDySRL/lib/python3.6/site-packages/flask/_compat.py", line 33, in reraise
    raise value
  File "/home/django/.local/share/virtualenvs/flask-backend-4nHDySRL/lib/python3.6/site-packages/flask/app.py", line 1475, in full_dispatch_request
    rv = self.dispatch_request()
  File "/home/django/.local/share/virtualenvs/flask-backend-4nHDySRL/lib/python3.6/site-packages/flask/app.py", line 1461, in dispatch_request
    return self.view_functions[rule.endpoint](**req.view_args)
  File "parser.py", line 90, in convert
    values = json.loads(values)
  File "/usr/lib/python3.6/json/__init__.py", line 354, in loads
    return _default_decoder.decode(s)
  File "/usr/lib/python3.6/json/decoder.py", line 339, in decode
    obj, end = self.raw_decode(s, idx=_w(s, 0).end())
  File "/usr/lib/python3.6/json/decoder.py", line 355, in raw_decode
    obj, end = self.scan_once(s, idx)
json.decoder.JSONDecodeError: Expecting ':' delimiter: line 1 column 5 (char 4)
2019-02-18 13:54:38,873 - __main__ - ERROR - Exception on /convert [POST]
Traceback (most recent call last):
  File "/home/django/.local/share/virtualenvs/flask-backend-4nHDySRL/lib/python3.6/site-packages/flask/app.py", line 1817, in wsgi_app
    response = self.full_dispatch_request()
  File "/home/django/.local/share/virtualenvs/flask-backend-4nHDySRL/lib/python3.6/site-packages/flask/app.py", line 1477, in full_dispatch_request
    rv = self.handle_user_exception(e)
  File "/home/django/.local/share/virtualenvs/flask-backend-4nHDySRL/lib/python3.6/site-packages/flask_cors/extension.py", line 161, in wrapped_function
    return cors_after_request(app.make_response(f(*args, **kwargs)))
  File "/home/django/.local/share/virtualenvs/flask-backend-4nHDySRL/lib/python3.6/site-packages/flask/app.py", line 1381, in handle_user_exception
    reraise(exc_type, exc_value, tb)
  File "/home/django/.local/share/virtualenvs/flask-backend-4nHDySRL/lib/python3.6/site-packages/flask/_compat.py", line 33, in reraise
    raise value
  File "/home/django/.local/share/virtualenvs/flask-backend-4nHDySRL/lib/python3.6/site-packages/flask/app.py", line 1475, in full_dispatch_request
    rv = self.dispatch_request()
  File "/home/django/.local/share/virtualenvs/flask-backend-4nHDySRL/lib/python3.6/site-packages/flask/app.py", line 1461, in dispatch_request
    return self.view_functions[rule.endpoint](**req.view_args)
  File "parser.py", line 91, in convert
    print(hit)
NameError: name 'hit' is not defined
